Workbook
Name cf: [1]BD!$F$17:$F$19

Sheet بيانات التلاميذ في المادة 
B1: المعالجة البيداغوجية لنتائج تقييم مكتسبات مرحلة التعليم الابتدائي
B2: البطاقة التحليلية لتقييم الكفاءات الختامية في البعد التكنولوجي
C3: الكفاءة الختامية 1 | G3: الكفاءة الختامية2 | J3: سلم التقدير | N3: المعنيين بالمعالجة
A4: اسم التلميذ | C4: م1 | D4: م2 | E4: م3 | F4: م4 | G4: م1 | H4: م2 | I4: م3 | J4: أ | K4: ب | L4: ج | M4: د | N4: ك.خ.1 | O4: ك.خ.2
A5: ريتاج أمبارك | C5: د | D5: ج | E5: ج | F5: د | G5: د | H5: د | I5: د | J5: =COUNTIF(C5:I5,"أ") -> 0 | K5: =COUNTIF(C5:I5,"ب") -> 0 | L5: =COUNTIF(C5:I5,"ج") -> 2 | M5: =COUNTIF(C5:I5,"د") -> 5 | N5: =IF(COUNTIF(C5:F5,"ج")+COUNTIF(C5:F5,"د")>=1,"X"," ") -> X | O5: =IF(COUNTIF(G5:I5,"ج")+COUNTIF(G5:I5,"د")>=1,"X"," ") -> X | Q5: م1 | R5: تحديد شروط احتراق بعض الغازات و مخاطر الاحتراق الغير آمن
A6: محمد الرشيد بربارة | C6: ب | D6: ج | E6: ج | F6: ج | G6: ب | H6: ب | I6: ب | J6: =COUNTIF(C6:I6,"أ") -> 0 | K6: =COUNTIF(C6:I6,"ب") -> 4 | L6: =COUNTIF(C6:I6,"ج") -> 3 | M6: =COUNTIF(C6:I6,"د") -> 0 | N6: =IF(COUNTIF(C6:F6,"ج")+COUNTIF(C6:F6,"د")>=1,"X"," ") -> X | O6: =IF(COUNTIF(G6:I6,"ج")+COUNTIF(G6:I6,"د")>=1,"X"," ") | Q6: م2 | R6: قراءة ارشادات الاستخدام الآمن للمواد و توظيفها
A7: محمد عماد الدين بلمختار | C7: أ | D7: أ | E7: أ | F7: أ | G7: أ | H7: أ | I7: ب | J7: =COUNTIF(C7:I7,"أ") -> 6 | K7: =COUNTIF(C7:I7,"ب") -> 1 | L7: =COUNTIF(C7:I7,"ج") -> 0 | M7: =COUNTIF(C7:I7,"د") -> 0 | N7: =IF(COUNTIF(C7:F7,"ج")+COUNTIF(C7:F7,"د")>=1,"X"," ") | O7: =IF(COUNTIF(G7:I7,"ج")+COUNTIF(G7:I7,"د")>=1,"X"," ") | Q7: م3 | R7: اختيار المنبع المناسب لتغذية الأجهزة الكهربائية مع الأمن
A8: بن علي بن زوبير | C8: ب | D8: أ | E8: ب | F8: أ | G8: ب | H8: ب | I8: ج | J8: =COUNTIF(C8:I8,"أ") -> 2 | K8: =COUNTIF(C8:I8,"ب") -> 4 | L8: =COUNTIF(C8:I8,"ج") -> 1 | M8: =COUNTIF(C8:I8,"د") -> 0 | N8: =IF(COUNTIF(C8:F8,"ج")+COUNTIF(C8:F8,"د")>=1,"X"," ") | O8: =IF(COUNTIF(G8:I8,"ج")+COUNTIF(G8:I8,"د")>=1,"X"," ") -> X | Q8: م4 | R8: الالتزام بالقواعد الأمنية للحماية من مخاطر التكهرب
A9: محمد إسلام بن زينب | C9: ب | D9: ب | E9: ب | F9: ب | G9: أ | H9: أ | I9: أ | J9: =COUNTIF(C9:I9,"أ") -> 3 | K9: =COUNTIF(C9:I9,"ب") -> 4 | L9: =COUNTIF(C9:I9,"ج") -> 0 | M9: =COUNTIF(C9:I9,"د") -> 0 | N9: =IF(COUNTIF(C9:F9,"ج")+COUNTIF(C9:F9,"د")>=1,"X"," ") | O9: =IF(COUNTIF(G9:I9,"ج")+COUNTIF(G9:I9,"د")>=1,"X"," ") | Q9: م1 | R9: تفسير الظواهر الفلكية حركة الأرض مع الشمس
A10: مارية بن طاع الله | C10: أ | D10: أ | E10: أ | F10: أ | G10: أ | H10: أ | I10: أ | J10: =COUNTIF(C10:I10,"أ") -> 7 | K10: =COUNTIF(C10:I10,"ب") -> 0 | L10: =COUNTIF(C10:I10,"ج") -> 0 | M10: =COUNTIF(C10:I10,"د") -> 0 | N10: =IF(COUNTIF(C10:F10,"ج")+COUNTIF(C10:F10,"د")>=1,"X"," ") | O10: =IF(COUNTIF(G10:I10,"ج")+COUNTIF(G10:I10,"د")>=1,"X"," ") | Q10: م2 | R10: ابراز مميزات الفصول الأربعة
A11: محمد بن طيب | C11: ج | D11: ج | E11: ج | F11: ج | G11: ج | H11: د | I11: د | J11: =COUNTIF(C11:I11,"أ") -> 0 | K11: =COUNTIF(C11:I11,"ب") -> 0 | L11: =COUNTIF(C11:I11,"ج") -> 5 | M11: =COUNTIF(C11:I11,"د") -> 2 | N11: =IF(COUNTIF(C11:F11,"ج")+COUNTIF(C11:F11,"د")>=1,"X"," ") -> X | O11: =IF(COUNTIF(G11:I11,"ج")+COUNTIF(G11:I11,"د")>=1,"X"," ") -> X | Q11: م3 | R11: تكييف الأنشطة الحياتية مع متطلبات و خصائص كل فصل
A12: نضال سليم بن عابد | C12: ج | D12: ج | E12: ب | F12: ب | G12: د | H12: أ | I12: ب | J12: =COUNTIF(C12:I12,"أ") -> 1 | K12: =COUNTIF(C12:I12,"ب") -> 3 | L12: =COUNTIF(C12:I12,"ج") -> 2 | M12: =COUNTIF(C12:I12,"د") -> 1 | N12: =IF(COUNTIF(C12:F12,"ج")+COUNTIF(C12:F12,"د")>=1,"X"," ") -> X | O12: =IF(COUNTIF(G12:I12,"ج")+COUNTIF(G12:I12,"د")>=1,"X"," ") -> X
A13: شهرزاد بوراس | C13: ج | D13: ج | E13: ج | F13: ج | G13: ب | H13: ج | I13: ج | J13: =COUNTIF(C13:I13,"أ") -> 0 | K13: =COUNTIF(C13:I13,"ب") -> 1 | L13: =COUNTIF(C13:I13,"ج") -> 6 | M13: =COUNTIF(C13:I13,"د") -> 0 | N13: =IF(COUNTIF(C13:F13,"ج")+COUNTIF(C13:F13,"د")>=1,"X"," ") -> X | O13: =IF(COUNTIF(G13:I13,"ج")+COUNTIF(G13:I13,"د")>=1,"X"," ") -> X
A14: فراح بوزيتونة | C14: د | D14: ج | E14: ج | F14: د | G14: ج | H14: د | I14: ج | J14: =COUNTIF(C14:I14,"أ") -> 0 | K14: =COUNTIF(C14:I14,"ب") -> 0 | L14: =COUNTIF(C14:I14,"ج") -> 4 | M14: =COUNTIF(C14:I14,"د") -> 3 | N14: =IF(COUNTIF(C14:F14,"ج")+COUNTIF(C14:F14,"د")>=1,"X"," ") -> X | O14: =IF(COUNTIF(G14:I14,"ج")+COUNTIF(G14:I14,"د")>=1,"X"," ") -> X
A15: ياسر عبد المالك بوعلام | C15: ج | D15: ب | E15: ب | F15: ج | G15: ج | H15: ج | I15: ج | J15: =COUNTIF(C15:I15,"أ") -> 0 | K15: =COUNTIF(C15:I15,"ب") -> 2 | L15: =COUNTIF(C15:I15,"ج") -> 5 | M15: =COUNTIF(C15:I15,"د") -> 0 | N15: =IF(COUNTIF(C15:F15,"ج")+COUNTIF(C15:F15,"د")>=1,"X"," ") -> X | O15: =IF(COUNTIF(G15:I15,"ج")+COUNTIF(G15:I15,"د")>=1,"X"," ") -> X
A16: ابراهيم الخليل بومالة | C16: أ | D16: أ | E16: أ | F16: أ | G16: ب | H16: ب | I16: ب | J16: =COUNTIF(C16:I16,"أ") -> 4 | K16: =COUNTIF(C16:I16,"ب") -> 3 | L16: =COUNTIF(C16:I16,"ج") -> 0 | M16: =COUNTIF(C16:I16,"د") -> 0 | N16: =IF(COUNTIF(C16:F16,"ج")+COUNTIF(C16:F16,"د")>=1,"X"," ") | O16: =IF(COUNTIF(G16:I16,"ج")+COUNTIF(G16:I16,"د")>=1,"X"," ")
A17: عبد القادر بونوح | C17: ج | D17: ج | E17: ج | F17: ج | G17: ج | H17: د | I17: ج | J17: =COUNTIF(C17:I17,"أ") -> 0 | K17: =COUNTIF(C17:I17,"ب") -> 0 | L17: =COUNTIF(C17:I17,"ج") -> 6 | M17: =COUNTIF(C17:I17,"د") -> 1 | N17: =IF(COUNTIF(C17:F17,"ج")+COUNTIF(C17:F17,"د")>=1,"X"," ") -> X | O17: =IF(COUNTIF(G17:I17,"ج")+COUNTIF(G17:I17,"د")>=1,"X"," ") -> X
A18: أنفال تجيني | C18: أ | D18: أ | E18: أ | F18: أ | G18: أ | H18: د | I18: د | J18: =COUNTIF(C18:I18,"أ") -> 5 | K18: =COUNTIF(C18:I18,"ب") -> 0 | L18: =COUNTIF(C18:I18,"ج") -> 0 | M18: =COUNTIF(C18:I18,"د") -> 2 | N18: =IF(COUNTIF(C18:F18,"ج")+COUNTIF(C18:F18,"د")>=1,"X"," ") | O18: =IF(COUNTIF(G18:I18,"ج")+COUNTIF(G18:I18,"د")>=1,"X"," ") -> X
A19: محمد عبد الرحمان تواتي | C19: غ | D19: غ | E19: غ | F19: غ | G19: غ | H19: غ | I19: غ | J19: =COUNTIF(C19:I19,"أ") -> 0 | K19: =COUNTIF(C19:I19,"ب") -> 0 | L19: =COUNTIF(C19:I19,"ج") -> 0 | M19: =COUNTIF(C19:I19,"د") -> 0 | N19: =IF(COUNTIF(C19:F19,"ج")+COUNTIF(C19:F19,"د")>=1,"X"," ") | O19: =IF(COUNTIF(G19:I19,"ج")+COUNTIF(G19:I19,"د")>=1,"X"," ")
A20: أسماء جوماد | C20: أ | D20: أ | E20: أ | F20: أ | G20: أ | H20: أ | I20: أ | J20: =COUNTIF(C20:I20,"أ") -> 7 | K20: =COUNTIF(C20:I20,"ب") -> 0 | L20: =COUNTIF(C20:I20,"ج") -> 0 | M20: =COUNTIF(C20:I20,"د") -> 0 | N20: =IF(COUNTIF(C20:F20,"ج")+COUNTIF(C20:F20,"د")>=1,"X"," ") | O20: =IF(COUNTIF(G20:I20,"ج")+COUNTIF(G20:I20,"د")>=1,"X"," ")
A21: يونس لطفي حراث | C21: أ | D21: ب | E21: أ | F21: أ | G21: ب | H21: أ | I21: د | J21: =COUNTIF(C21:I21,"أ") -> 4 | K21: =COUNTIF(C21:I21,"ب") -> 2 | L21: =COUNTIF(C21:I21,"ج") -> 0 | M21: =COUNTIF(C21:I21,"د") -> 1 | N21: =IF(COUNTIF(C21:F21,"ج")+COUNTIF(C21:F21,"د")>=1,"X"," ") | O21: =IF(COUNTIF(G21:I21,"ج")+COUNTIF(G21:I21,"د")>=1,"X"," ") -> X
A22: فريال قطر الندى دهوي | C22: ب | D22: ب | E22: ب | F22: ب | G22: ج | H22: ج | I22: ج | J22: =COUNTIF(C22:I22,"أ") -> 0 | K22: =COUNTIF(C22:I22,"ب") -> 4 | L22: =COUNTIF(C22:I22,"ج") -> 3 | M22: =COUNTIF(C22:I22,"د") -> 0 | N22: =IF(COUNTIF(C22:F22,"ج")+COUNTIF(C22:F22,"د")>=1,"X"," ") | O22: =IF(COUNTIF(G22:I22,"ج")+COUNTIF(G22:I22,"د")>=1,"X"," ") -> X
A23: مايا سبيحي | C23: أ | D23: أ | E23: أ | F23: أ | G23: أ | H23: أ | I23: أ | J23: =COUNTIF(C23:I23,"أ") -> 7 | K23: =COUNTIF(C23:I23,"ب") -> 0 | L23: =COUNTIF(C23:I23,"ج") -> 0 | M23: =COUNTIF(C23:I23,"د") -> 0 | N23: =IF(COUNTIF(C23:F23,"ج")+COUNTIF(C23:F23,"د")>=1,"X"," ") | O23: =IF(COUNTIF(G23:I23,"ج")+COUNTIF(G23:I23,"د")>=1,"X"," ")
... A43: معاذ مقدم | C43: أ | D43: أ | E43: أ | F43: ب | G43: ج | H43: أ | I43: أ | J43: =COUNTIF(C43:I43,"أ") -> 5 | K43: =COUNTIF(C43:I43,"ب") -> 1 | L43: =COUNTIF(C43:I43,"ج") -> 1 | M43: =COUNTIF(C43:I43,"د") -> 0 | N43: =IF(COUNTIF(C43:F43,"ج")+COUNTIF(C43:F43,"د")>=1,"X"," ") | O43: =IF(COUNTIF(G43:I43,"ج")+COUNTIF(G43:I43,"د")>=1,"X"," ") -> X
C44: ب | D44: أ | E44: أ | F44: أ | G44: أ | H44: ج | I44: أ | J44: =COUNTIF(C44:I44,"أ") -> 5 | K44: =COUNTIF(C44:I44,"ب") -> 1 | L44: =COUNTIF(C44:I44,"ج") -> 1 | M44: =COUNTIF(C44:I44,"د") -> 0 | N44: =IF(COUNTIF(C44:F44,"ج")+COUNTIF(C44:F44,"د")>=1,"X"," ") | O44: =IF(COUNTIF(G44:I44,"ج")+COUNTIF(G44:I44,"د")>=1,"X"," ") -> X
A45: هبة مول الخلوة | C45: أ | D45: أ | E45: أ | F45: أ | G45: د | H45: أ | I45: أ | J45: =COUNTIF(C45:I45,"أ") -> 6 | K45: =COUNTIF(C45:I45,"ب") -> 0 | L45: =COUNTIF(C45:I45,"ج") -> 0 | M45: =COUNTIF(C45:I45,"د") -> 1 | N45: =IF(COUNTIF(C45:F45,"ج")+COUNTIF(C45:F45,"د")>=1,"X"," ") | O45: =IF(COUNTIF(G45:I45,"ج")+COUNTIF(G45:I45,"د")>=1,"X"," ") -> X
A46: سحر ميسوم | C46: ب | D46: أ | E46: ب | F46: ب | G46: ج | H46: ج | I46: ج | J46: =COUNTIF(C46:I46,"أ") -> 1 | K46: =COUNTIF(C46:I46,"ب") -> 3 | L46: =COUNTIF(C46:I46,"ج") -> 3 | M46: =COUNTIF(C46:I46,"د") -> 0 | N46: =IF(COUNTIF(C46:F46,"ج")+COUNTIF(C46:F46,"د")>=1,"X"," ") | O46: =IF(COUNTIF(G46:I46,"ج")+COUNTIF(G46:I46,"د")>=1,"X"," ") -> X
A47: احمد وائل الحسين وراد | C47: ب | D47: ب | E47: ب | F47: ب | G47: أ | H47: أ | I47: أ | J47: =COUNTIF(C47:I47,"أ") -> 3 | K47: =COUNTIF(C47:I47,"ب") -> 4 | L47: =COUNTIF(C47:I47,"ج") -> 0 | M47: =COUNTIF(C47:I47,"د") -> 0 | N47: =IF(COUNTIF(C47:F47,"ج")+COUNTIF(C47:F47,"د")>=1,"X"," ") | O47: =IF(COUNTIF(G47:I47,"ج")+COUNTIF(G47:I47,"د")>=1,"X"," ")
A48: سارة يحياوي | C48: أ | D48: أ | E48: أ | F48: أ | G48: أ | H48: د | I48: د | J48: =COUNTIF(C48:I48,"أ") -> 5 | K48: =COUNTIF(C48:I48,"ب") -> 0 | L48: =COUNTIF(C48:I48,"ج") -> 0 | M48: =COUNTIF(C48:I48,"د") -> 2 | N48: =IF(COUNTIF(C48:F48,"ج")+COUNTIF(C48:F48,"د")>=1,"X"," ") | O48: =IF(COUNTIF(G48:I48,"ج")+COUNTIF(G48:I48,"د")>=1,"X"," ") -> X
J49: =COUNTIF(C49:I49,"أ") -> 0 | K49: =COUNTIF(C49:I49,"ب") -> 0 | L49: =COUNTIF(C49:I49,"ج") -> 0 | M49: =COUNTIF(C49:I49,"د") -> 0 | N49: =IF(COUNTIF(C49:F49,"ج")+COUNTIF(C49:F49,"د")>=1,"X"," ") | O49: =IF(COUNTIF(G49:I49,"ج")+COUNTIF(G49:I49,"د")>=1,"X"," ")
J50: =COUNTIF(C50:I50,"أ") -> 0 | K50: =COUNTIF(C50:I50,"ب") -> 0 | L50: =COUNTIF(C50:I50,"ج") -> 0 | M50: =COUNTIF(C50:I50,"د") -> 0 | N50: =IF(COUNTIF(C50:F50,"ج")+COUNTIF(C50:F50,"د")>=1,"X"," ") | O50: =IF(COUNTIF(G50:I50,"ج")+COUNTIF(G50:I50,"د")>=1,"X"," ")
J51: =COUNTIF(C51:I51,"أ") -> 0 | K51: =COUNTIF(C51:I51,"ب") -> 0 | L51: =COUNTIF(C51:I51,"ج") -> 0 | M51: =COUNTIF(C51:I51,"د") -> 0 | N51: =IF(COUNTIF(C51:F51,"ج")+COUNTIF(C51:F51,"د")>=1,"X"," ") | O51: =IF(COUNTIF(G51:I51,"ج")+COUNTIF(G51:I51,"د")>=1,"X"," ")
J52: =COUNTIF(C52:I52,"أ") -> 0 | K52: =COUNTIF(C52:I52,"ب") -> 0 | L52: =COUNTIF(C52:I52,"ج") -> 0 | M52: =COUNTIF(C52:I52,"د") -> 0 | N52: =IF(COUNTIF(C52:F52,"ج")+COUNTIF(C52:F52,"د")>=1,"X"," ") | O52: =IF(COUNTIF(G52:I52,"ج")+COUNTIF(G52:I52,"د")>=1,"X"," ")
J53: =COUNTIF(C53:I53,"أ") -> 0 | K53: =COUNTIF(C53:I53,"ب") -> 0 | L53: =COUNTIF(C53:I53,"ج") -> 0 | M53: =COUNTIF(C53:I53,"د") -> 0 | N53: =IF(COUNTIF(C53:F53,"ج")+COUNTIF(C53:F53,"د")>=1,"X"," ") | O53: =IF(COUNTIF(G53:I53,"ج")+COUNTIF(G53:I53,"د")>=1,"X"," ")
J54: =COUNTIF(C54:I54,"أ") -> 0 | K54: =COUNTIF(C54:I54,"ب") -> 0 | L54: =COUNTIF(C54:I54,"ج") -> 0 | M54: =COUNTIF(C54:I54,"د") -> 0 | N54: =IF(COUNTIF(C54:F54,"ج")+COUNTIF(C54:F54,"د")>=1,"X"," ") | O54: =IF(COUNTIF(G54:I54,"ج")+COUNTIF(G54:I54,"د")>=1,"X"," ")
A55: أ | C55: =COUNTIF(C5:C54,"أ") -> 17 | D55: =COUNTIF(D5:D54,"أ") -> 18 | E55: =COUNTIF(E5:E54,"أ") -> 17 | F55: =COUNTIF(F5:F54,"أ") -> 17 | G55: =COUNTIF(G5:G54,"أ") -> 18 | H55: =COUNTIF(H5:H54,"أ") -> 20 | I55: =COUNTIF(I5:I54,"أ") -> 17 | J55: =SUM(J5:J54) -> 124 | N55: =COUNTIF(N5:N54,"X") -> 13 | O55: =COUNTIF(O5:O54,"X") -> 20
A56: ب | C56: =COUNTIF(C5:C54,"ب") -> 13 | D56: =COUNTIF(D5:D54,"ب") -> 10 | E56: =COUNTIF(E5:E54,"ب") -> 15 | F56: =COUNTIF(F5:F54,"ب") -> 13 | G56: =COUNTIF(G5:G54,"ب") -> 8 | H56: =COUNTIF(H5:H54,"ب") -> 7 | I56: =COUNTIF(I5:I54,"ب") -> 8 | K56: =SUM(K6:K55) -> 74
A57: ج | C57: =COUNTIF(C5:C54,"ج") -> 7 | D57: =COUNTIF(D5:D54,"ج") -> 11 | E57: =COUNTIF(E5:E54,"ج") -> 7 | F57: =COUNTIF(F5:F54,"ج") -> 7 | G57: =COUNTIF(G5:G54,"ج") -> 8 | H57: =COUNTIF(H5:H54,"ج") -> 6 | I57: =COUNTIF(I5:I54,"ج") -> 8 | L57: =SUM(L7:L56) -> 49
A58: د | C58: =COUNTIF(C5:C54,"د") -> 3 | D58: =COUNTIF(D5:D54,"د") -> 1 | E58: =COUNTIF(E5:E54,"د") -> 1 | F58: =COUNTIF(F5:F54,"د") -> 3 | G58: =COUNTIF(G5:G54,"د") -> 6 | H58: =COUNTIF(H5:H54,"د") -> 7 | I58: =COUNTIF(I5:I54,"د") -> 7 | M58: =SUM(M8:M57) -> 23
A59: الغياب | C59: =COUNTIF(C5:C54,"غ") -> 4 | D59: =COUNTIF(D5:D54,"غ") -> 4 | E59: =COUNTIF(E5:E54,"غ") -> 4 | F59: =COUNTIF(F5:F54,"غ") -> 4 | G59: =COUNTIF(G5:G54,"غ") -> 4 | H59: =COUNTIF(H5:H54,"غ") -> 4 | I59: =COUNTIF(I5:I54,"غ") -> 4

Sheet بيانات التلاميذ الكفاءة 1
B1: المعالجة البيداغوجية لنتائج تقييم مكتسبات مرحلة التعليم الابتدائي
B2: البطاقة التحليلية لتقييم الكفاءات الختامية في البعد التكنولوجي
C3: الكفاءة الختامية 1 | G3: سلم التقدير | K3: المعنيين بالمعالجة
A4: اسم التلميذ | C4: م1 | D4: م2 | E4: م3 | F4: م4 | G4: أ | H4: ب | I4: ج | J4: د | K4: في الكفاءة الختامية 1
A5: ='بيانات التلاميذ في المادة '!A5:B5 -> ريتاج أمبارك | C5: ='بيانات التلاميذ في المادة '!C5 -> د | D5: ='بيانات التلاميذ في المادة '!D5 -> ج | E5: ='بيانات التلاميذ في المادة '!E5 -> ج | F5: ='بيانات التلاميذ في المادة '!F5 -> د | G5: =COUNTIF(C5:F5,"أ") -> 0 | H5: =COUNTIF(C5:F5,"ب") -> 0 | I5: =COUNTIF(C5:F5,"ج") -> 2 | J5: =COUNTIF(C5:F5,"د") -> 2 | K5: =IF(COUNTIF(C5:F5,"ج")+COUNTIF(C5:F5,"د")>=1,"X"," ") -> X | M5: م1 | N5: تحديد شروط احتراق بعض الغازات و مخاطر الاحتراق الغير آمن
A6: ='بيانات التلاميذ في المادة '!A6:B6 -> محمد الرشيد بربارة | C6: ='بيانات التلاميذ في المادة '!C6 -> ب | D6: ='بيانات التلاميذ في المادة '!D6 -> ج | E6: ='بيانات التلاميذ في المادة '!E6 -> ج | F6: ='بيانات التلاميذ في المادة '!F6 -> ج | G6: =COUNTIF(C6:F6,"أ") -> 0 | H6: =COUNTIF(C6:F6,"ب") -> 1 | I6: =COUNTIF(C6:F6,"ج") -> 3 | J6: =COUNTIF(C6:F6,"د") -> 0 | K6: =IF(COUNTIF(C6:F6,"ج")+COUNTIF(C6:F6,"د")>=1,"X"," ") -> X | M6: م2 | N6: قراءة ارشادات الاستخدام الآمن للمواد و توظيفها
A7: ='بيانات التلاميذ في المادة '!A7:B7 -> محمد عماد الدين بلمختار | C7: ='بيانات التلاميذ في المادة '!C7 -> أ | D7: ='بيانات التلاميذ في المادة '!D7 -> أ | E7: ='بيانات التلاميذ في المادة '!E7 -> أ | F7: ='بيانات التلاميذ في المادة '!F7 -> أ | G7: =COUNTIF(C7:F7,"أ") -> 4 | H7: =COUNTIF(C7:F7,"ب") -> 0 | I7: =COUNTIF(C7:F7,"ج") -> 0 | J7: =COUNTIF(C7:F7,"د") -> 0 | K7: =IF(COUNTIF(C7:F7,"ج")+COUNTIF(C7:F7,"د")>=1,"X"," ") | M7: م3 | N7: اختيار المنبع المناسب لتغذية الأجهزة الكهربائية مع الأمن
A8: ='بيانات التلاميذ في المادة '!A8:B8 -> بن علي بن زوبير | C8: ='بيانات التلاميذ في المادة '!C8 -> ب | D8: ='بيانات التلاميذ في المادة '!D8 -> أ | E8: ='بيانات التلاميذ في المادة '!E8 -> ب | F8: ='بيانات التلاميذ في المادة '!F8 -> أ | G8: =COUNTIF(C8:F8,"أ") -> 2 | H8: =COUNTIF(C8:F8,"ب") -> 2 | I8: =COUNTIF(C8:F8,"ج") -> 0 | J8: =COUNTIF(C8:F8,"د") -> 0 | K8: =IF(COUNTIF(C8:F8,"ج")+COUNTIF(C8:F8,"د")>=1,"X"," ") | M8: م4 | N8: الالتزام بالقواعد الأمنية للحماية من مخاطر التكهرب
A9: ='بيانات التلاميذ في المادة '!A9:B9 -> محمد إسلام بن زينب | C9: ='بيانات التلاميذ في المادة '!C9 -> ب | D9: ='بيانات التلاميذ في المادة '!D9 -> ب | E9: ='بيانات التلاميذ في المادة '!E9 -> ب | F9: ='بيانات التلاميذ في المادة '!F9 -> ب | G9: =COUNTIF(C9:F9,"أ") -> 0 | H9: =COUNTIF(C9:F9,"ب") -> 4 | I9: =COUNTIF(C9:F9,"ج") -> 0 | J9: =COUNTIF(C9:F9,"د") -> 0 | K9: =IF(COUNTIF(C9:F9,"ج")+COUNTIF(C9:F9,"د")>=1,"X"," ")
A10: ='بيانات التلاميذ في المادة '!A10:B10 -> مارية بن طاع الله | C10: ='بيانات التلاميذ في المادة '!C10 -> أ | D10: ='بيانات التلاميذ في المادة '!D10 -> أ | E10: ='بيانات التلاميذ في المادة '!E10 -> أ | F10: ='بيانات التلاميذ في المادة '!F10 -> أ | G10: =COUNTIF(C10:F10,"أ") -> 4 | H10: =COUNTIF(C10:F10,"ب") -> 0 | I10: =COUNTIF(C10:F10,"ج") -> 0 | J10: =COUNTIF(C10:F10,"د") -> 0 | K10: =IF(COUNTIF(C10:F10,"ج")+COUNTIF(C10:F10,"د")>=1,"X"," ")
A11: ='بيانات التلاميذ في المادة '!A11:B11 -> محمد بن طيب | C11: ='بيانات التلاميذ في المادة '!C11 -> ج | D11: ='بيانات التلاميذ في المادة '!D11 -> ج | E11: ='بيانات التلاميذ في المادة '!E11 -> ج | F11: ='بيانات التلاميذ في المادة '!F11 -> ج | G11: =COUNTIF(C11:F11,"أ") -> 0 | H11: =COUNTIF(C11:F11,"ب") -> 0 | I11: =COUNTIF(C11:F11,"ج") -> 4 | J11: =COUNTIF(C11:F11,"د") -> 0 | K11: =IF(COUNTIF(C11:F11,"ج")+COUNTIF(C11:F11,"د")>=1,"X"," ") -> X
A12: ='بيانات التلاميذ في المادة '!A12:B12 -> نضال سليم بن عابد | C12: ='بيانات التلاميذ في المادة '!C12 -> ج | D12: ='بيانات التلاميذ في المادة '!D12 -> ج | E12: ='بيانات التلاميذ في المادة '!E12 -> ب | F12: ='بيانات التلاميذ في المادة '!F12 -> ب | G12: =COUNTIF(C12:F12,"أ") -> 0 | H12: =COUNTIF(C12:F12,"ب") -> 2 | I12: =COUNTIF(C12:F12,"ج") -> 2 | J12: =COUNTIF(C12:F12,"د") -> 0 | K12: =IF(COUNTIF(C12:F12,"ج")+COUNTIF(C12:F12,"د")>=1,"X"," ") -> X
A13: ='بيانات التلاميذ في المادة '!A13:B13 -> شهرزاد بوراس | C13: ='بيانات التلاميذ في المادة '!C13 -> ج | D13: ='بيانات التلاميذ في المادة '!D13 -> ج | E13: ='بيانات التلاميذ في المادة '!E13 -> ج | F13: ='بيانات التلاميذ في المادة '!F13 -> ج | G13: =COUNTIF(C13:F13,"أ") -> 0 | H13: =COUNTIF(C13:F13,"ب") -> 0 | I13: =COUNTIF(C13:F13,"ج") -> 4 | J13: =COUNTIF(C13:F13,"د") -> 0 | K13: =IF(COUNTIF(C13:F13,"ج")+COUNTIF(C13:F13,"د")>=1,"X"," ") -> X
A14: ='بيانات التلاميذ في المادة '!A14:B14 -> فراح بوزيتونة | C14: ='بيانات التلاميذ في المادة '!C14 -> د | D14: ='بيانات التلاميذ في المادة '!D14 -> ج | E14: ='بيانات التلاميذ في المادة '!E14 -> ج | F14: ='بيانات التلاميذ في المادة '!F14 -> د | G14: =COUNTIF(C14:F14,"أ") -> 0 | H14: =COUNTIF(C14:F14,"ب") -> 0 | I14: =COUNTIF(C14:F14,"ج") -> 2 | J14: =COUNTIF(C14:F14,"د") -> 2 | K14: =IF(COUNTIF(C14:F14,"ج")+COUNTIF(C14:F14,"د")>=1,"X"," ") -> X
A15: ='بيانات التلاميذ في المادة '!A15:B15 -> ياسر عبد المالك بوعلام | C15: ='بيانات التلاميذ في المادة '!C15 -> ج | D15: ='بيانات التلاميذ في المادة '!D15 -> ب | E15: ='بيانات التلاميذ في المادة '!E15 -> ب | F15: ='بيانات التلاميذ في المادة '!F15 -> ج | G15: =COUNTIF(C15:F15,"أ") -> 0 | H15: =COUNTIF(C15:F15,"ب") -> 2 | I15: =COUNTIF(C15:F15,"ج") -> 2 | J15: =COUNTIF(C15:F15,"د") -> 0 | K15: =IF(COUNTIF(C15:F15,"ج")+COUNTIF(C15:F15,"د")>=1,"X"," ") -> X
A16: ='بيانات التلاميذ في المادة '!A16:B16 -> ابراهيم الخليل بومالة | C16: ='بيانات التلاميذ في المادة '!C16 -> أ | D16: ='بيانات التلاميذ في المادة '!D16 -> أ | E16: ='بيانات التلاميذ في المادة '!E16 -> أ | F16: ='بيانات التلاميذ في المادة '!F16 -> أ | G16: =COUNTIF(C16:F16,"أ") -> 4 | H16: =COUNTIF(C16:F16,"ب") -> 0 | I16: =COUNTIF(C16:F16,"ج") -> 0 | J16: =COUNTIF(C16:F16,"د") -> 0 | K16: =IF(COUNTIF(C16:F16,"ج")+COUNTIF(C16:F16,"د")>=1,"X"," ")
A17: ='بيانات التلاميذ في المادة '!A17:B17 -> عبد القادر بونوح | C17: ='بيانات التلاميذ في المادة '!C17 -> ج | D17: ='بيانات التلاميذ في المادة '!D17 -> ج | E17: ='بيانات التلاميذ في المادة '!E17 -> ج | F17: ='بيانات التلاميذ في المادة '!F17 -> ج | G17: =COUNTIF(C17:F17,"أ") -> 0 | H17: =COUNTIF(C17:F17,"ب") -> 0 | I17: =COUNTIF(C17:F17,"ج") -> 4 | J17: =COUNTIF(C17:F17,"د") -> 0 | K17: =IF(COUNTIF(C17:F17,"ج")+COUNTIF(C17:F17,"د")>=1,"X"," ") -> X
A18: ='بيانات التلاميذ في المادة '!A18:B18 -> أنفال تجيني | C18: ='بيانات التلاميذ في المادة '!C18 -> أ | D18: ='بيانات التلاميذ في المادة '!D18 -> أ | E18: ='بيانات التلاميذ في المادة '!E18 -> أ | F18: ='بيانات التلاميذ في المادة '!F18 -> أ | G18: =COUNTIF(C18:F18,"أ") -> 4 | H18: =COUNTIF(C18:F18,"ب") -> 0 | I18: =COUNTIF(C18:F18,"ج") -> 0 | J18: =COUNTIF(C18:F18,"د") -> 0 | K18: =IF(COUNTIF(C18:F18,"ج")+COUNTIF(C18:F18,"د")>=1,"X"," ")
A19: ='بيانات التلاميذ في المادة '!A19:B19 -> محمد عبد الرحمان تواتي | C19: ='بيانات التلاميذ في المادة '!C19 -> غ | D19: ='بيانات التلاميذ في المادة '!D19 -> غ | E19: ='بيانات التلاميذ في المادة '!E19 -> غ | F19: ='بيانات التلاميذ في المادة '!F19 -> غ | G19: =COUNTIF(C19:F19,"أ") -> 0 | H19: =COUNTIF(C19:F19,"ب") -> 0 | I19: =COUNTIF(C19:F19,"ج") -> 0 | J19: =COUNTIF(C19:F19,"د") -> 0 | K19: =IF(COUNTIF(C19:F19,"ج")+COUNTIF(C19:F19,"د")>=1,"X"," ")
A20: ='بيانات التلاميذ في المادة '!A20:B20 -> أسماء جوماد | C20: ='بيانات التلاميذ في المادة '!C20 -> أ | D20: ='بيانات التلاميذ في المادة '!D20 -> أ | E20: ='بيانات التلاميذ في المادة '!E20 -> أ | F20: ='بيانات التلاميذ في المادة '!F20 -> أ | G20: =COUNTIF(C20:F20,"أ") -> 4 | H20: =COUNTIF(C20:F20,"ب") -> 0 | I20: =COUNTIF(C20:F20,"ج") -> 0 | J20: =COUNTIF(C20:F20,"د") -> 0 | K20: =IF(COUNTIF(C20:F20,"ج")+COUNTIF(C20:F20,"د")>=1,"X"," ")
... A54: ='بيانات التلاميذ في المادة '!A54:B54 -> 0 | C54: ='بيانات التلاميذ في المادة '!C54 -> 0 | D54: ='بيانات التلاميذ في المادة '!D54 -> 0 | E54: ='بيانات التلاميذ في المادة '!E54 -> 0 | F54: ='بيانات التلاميذ في المادة '!F54 -> 0 | G54: =COUNTIF(C54:F54,"أ") -> 0 | H54: =COUNTIF(C54:F54,"ب") -> 0 | I54: =COUNTIF(C54:F54,"ج") -> 0 | J54: =COUNTIF(C54:F54,"د") -> 0 | K54: =IF(COUNTIF(C54:F54,"ج")+COUNTIF(C54:F54,"د")>=1,"X"," ")
A55: أ | C55: =COUNTIF(C5:C54,"أ") -> 17 | D55: =COUNTIF(D5:D54,"أ") -> 18 | E55: =COUNTIF(E5:E54,"أ") -> 17 | F55: =COUNTIF(F5:F54,"أ") -> 17 | G55: =SUM(G5:G54) -> 69 | K55: =COUNTIF(K5:K54,"X") -> 13
A56: ب | C56: =COUNTIF(C5:C54,"ب") -> 13 | D56: =COUNTIF(D5:D54,"ب") -> 10 | E56: =COUNTIF(E5:E54,"ب") -> 15 | F56: =COUNTIF(F5:F54,"ب") -> 13 | H56: =SUM(H6:H55) -> 51
A57: ج | C57: =COUNTIF(C5:C54,"ج") -> 7 | D57: =COUNTIF(D5:D54,"ج") -> 11 | E57: =COUNTIF(E5:E54,"ج") -> 7 | F57: =COUNTIF(F5:F54,"ج") -> 7 | I57: =SUM(I7:I56) -> 27
A58: د | C58: =COUNTIF(C5:C54,"د") -> 3 | D58: =COUNTIF(D5:D54,"د") -> 1 | E58: =COUNTIF(E5:E54,"د") -> 1 | F58: =COUNTIF(F5:F54,"د") -> 3 | J58: =SUM(J8:J57) -> 6
A59: الغياب | C59: =COUNTIF(C5:C54,"غ") -> 4 | D59: =COUNTIF(D5:D54,"غ") -> 4 | E59: =COUNTIF(E5:E54,"غ") -> 4 | F59: =COUNTIF(F5:F54,"غ") -> 4

Sheet بيانات التلاميذ الكفاءة 2
B1: المعالجة البيداغوجية لنتائج تقييم مكتسبات مرحلة التعليم الابتدائي
B2: البطاقة التحليلية لتقييم الكفاءات الختامية في البعد التكنولوجي
C3: الكفاءة الختامية2 | F3: سلم التقدير | J3: المعنيين بالمعالجة
A4: اسم التلميذ | C4: م1 | D4: م2 | E4: م3 | F4: أ | G4: ب | H4: ج | I4: د | J4: في الكفاءة الختامية 2
A5: ='بيانات التلاميذ في المادة '!A5:B5 -> ريتاج أمبارك | C5: ='بيانات التلاميذ في المادة '!G5 -> د | D5: ='بيانات التلاميذ في المادة '!H5 -> د | E5: ='بيانات التلاميذ في المادة '!I5 -> د | F5: =COUNTIF(C5:E5,"أ") -> 0 | G5: =COUNTIF(C5:E5,"ب") -> 0 | H5: =COUNTIF(C5:E5,"ج") -> 0 | I5: =COUNTIF(C5:E5,"د") -> 3 | J5: =IF(COUNTIF(C5:E5,"ج")+COUNTIF(C5:E5,"د")>=1,"X"," ") -> X | M5: م1 | N5: تفسير الظواهر الفلكية حركة الأرض مع الشمس
A6: ='بيانات التلاميذ في المادة '!A6:B6 -> محمد الرشيد بربارة | C6: ='بيانات التلاميذ في المادة '!G6 -> ب | D6: ='بيانات التلاميذ في المادة '!H6 -> ب | E6: ='بيانات التلاميذ في المادة '!I6 -> ب | F6: =COUNTIF(C6:E6,"أ") -> 0 | G6: =COUNTIF(C6:E6,"ب") -> 3 | H6: =COUNTIF(C6:E6,"ج") -> 0 | I6: =COUNTIF(C6:E6,"د") -> 0 | J6: =IF(COUNTIF(C6:E6,"ج")+COUNTIF(C6:E6,"د")>=1,"X"," ") | M6: م2 | N6: ابراز مميزات الفصول الأربعة
A7: ='بيانات التلاميذ في المادة '!A7:B7 -> محمد عماد الدين بلمختار | C7: ='بيانات التلاميذ في المادة '!G7 -> أ | D7: ='بيانات التلاميذ في المادة '!H7 -> أ | E7: ='بيانات التلاميذ في المادة '!I7 -> ب | F7: =COUNTIF(C7:E7,"أ") -> 2 | G7: =COUNTIF(C7:E7,"ب") -> 1 | H7: =COUNTIF(C7:E7,"ج") -> 0 | I7: =COUNTIF(C7:E7,"د") -> 0 | J7: =IF(COUNTIF(C7:E7,"ج")+COUNTIF(C7:E7,"د")>=1,"X"," ") | M7: م3 | N7: تكييف الأنشطة الحياتية مع متطلبات و خصائص كل فصل
A8: ='بيانات التلاميذ في المادة '!A8:B8 -> بن علي بن زوبير | C8: ='بيانات التلاميذ في المادة '!G8 -> ب | D8: ='بيانات التلاميذ في المادة '!H8 -> ب | E8: ='بيانات التلاميذ في المادة '!I8 -> ج | F8: =COUNTIF(C8:E8,"أ") -> 0 | G8: =COUNTIF(C8:E8,"ب") -> 2 | H8: =COUNTIF(C8:E8,"ج") -> 1 | I8: =COUNTIF(C8:E8,"د") -> 0 | J8: =IF(COUNTIF(C8:E8,"ج")+COUNTIF(C8:E8,"د")>=1,"X"," ") -> X
A9: ='بيانات التلاميذ في المادة '!A9:B9 -> محمد إسلام بن زينب | C9: ='بيانات التلاميذ في المادة '!G9 -> أ | D9: ='بيانات التلاميذ في المادة '!H9 -> أ | E9: ='بيانات التلاميذ في المادة '!I9 -> أ | F9: =COUNTIF(C9:E9,"أ") -> 3 | G9: =COUNTIF(C9:E9,"ب") -> 0 | H9: =COUNTIF(C9:E9,"ج") -> 0 | I9: =COUNTIF(C9:E9,"د") -> 0 | J9: =IF(COUNTIF(C9:E9,"ج")+COUNTIF(C9:E9,"د")>=1,"X"," ")
A10: ='بيانات التلاميذ في المادة '!A10:B10 -> مارية بن طاع الله | C10: ='بيانات التلاميذ في المادة '!G10 -> أ | D10: ='بيانات التلاميذ في المادة '!H10 -> أ | E10: ='بيانات التلاميذ في المادة '!I10 -> أ | F10: =COUNTIF(C10:E10,"أ") -> 3 | G10: =COUNTIF(C10:E10,"ب") -> 0 | H10: =COUNTIF(C10:E10,"ج") -> 0 | I10: =COUNTIF(C10:E10,"د") -> 0 | J10: =IF(COUNTIF(C10:E10,"ج")+COUNTIF(C10:E10,"د")>=1,"X"," ")
A11: ='بيانات التلاميذ في المادة '!A11:B11 -> محمد بن طيب | C11: ='بيانات التلاميذ في المادة '!G11 -> ج | D11: ='بيانات التلاميذ في المادة '!H11 -> د | E11: ='بيانات التلاميذ في المادة '!I11 -> د | F11: =COUNTIF(C11:E11,"أ") -> 0 | G11: =COUNTIF(C11:E11,"ب") -> 0 | H11: =COUNTIF(C11:E11,"ج") -> 1 | I11: =COUNTIF(C11:E11,"د") -> 2 | J11: =IF(COUNTIF(C11:E11,"ج")+COUNTIF(C11:E11,"د")>=1,"X"," ") -> X
A12: ='بيانات التلاميذ في المادة '!A12:B12 -> نضال سليم بن عابد | C12: ='بيانات التلاميذ في المادة '!G12 -> د | D12: ='بيانات التلاميذ في المادة '!H12 -> أ | E12: ='بيانات التلاميذ في المادة '!I12 -> ب | F12: =COUNTIF(C12:E12,"أ") -> 1 | G12: =COUNTIF(C12:E12,"ب") -> 1 | H12: =COUNTIF(C12:E12,"ج") -> 0 | I12: =COUNTIF(C12:E12,"د") -> 1 | J12: =IF(COUNTIF(C12:E12,"ج")+COUNTIF(C12:E12,"د")>=1,"X"," ") -> X
A13: ='بيانات التلاميذ في المادة '!A13:B13 -> شهرزاد بوراس | C13: ='بيانات التلاميذ في المادة '!G13 -> ب | D13: ='بيانات التلاميذ في المادة '!H13 -> ج | E13: ='بيانات التلاميذ في المادة '!I13 -> ج | F13: =COUNTIF(C13:E13,"أ") -> 0 | G13: =COUNTIF(C13:E13,"ب") -> 1 | H13: =COUNTIF(C13:E13,"ج") -> 2 | I13: =COUNTIF(C13:E13,"د") -> 0 | J13: =IF(COUNTIF(C13:E13,"ج")+COUNTIF(C13:E13,"د")>=1,"X"," ") -> X
A14: ='بيانات التلاميذ في المادة '!A14:B14 -> فراح بوزيتونة | C14: ='بيانات التلاميذ في المادة '!G14 -> ج | D14: ='بيانات التلاميذ في المادة '!H14 -> د | E14: ='بيانات التلاميذ في المادة '!I14 -> ج | F14: =COUNTIF(C14:E14,"أ") -> 0 | G14: =COUNTIF(C14:E14,"ب") -> 0 | H14: =COUNTIF(C14:E14,"ج") -> 2 | I14: =COUNTIF(C14:E14,"د") -> 1 | J14: =IF(COUNTIF(C14:E14,"ج")+COUNTIF(C14:E14,"د")>=1,"X"," ") -> X
A15: ='بيانات التلاميذ في المادة '!A15:B15 -> ياسر عبد المالك بوعلام | C15: ='بيانات التلاميذ في المادة '!G15 -> ج | D15: ='بيانات التلاميذ في المادة '!H15 -> ج | E15: ='بيانات التلاميذ في المادة '!I15 -> ج | F15: =COUNTIF(C15:E15,"أ") -> 0 | G15: =COUNTIF(C15:E15,"ب") -> 0 | H15: =COUNTIF(C15:E15,"ج") -> 3 | I15: =COUNTIF(C15:E15,"د") -> 0 | J15: =IF(COUNTIF(C15:E15,"ج")+COUNTIF(C15:E15,"د")>=1,"X"," ") -> X
A16: ='بيانات التلاميذ في المادة '!A16:B16 -> ابراهيم الخليل بومالة | C16: ='بيانات التلاميذ في المادة '!G16 -> ب | D16: ='بيانات التلاميذ في المادة '!H16 -> ب | E16: ='بيانات التلاميذ في المادة '!I16 -> ب | F16: =COUNTIF(C16:E16,"أ") -> 0 | G16: =COUNTIF(C16:E16,"ب") -> 3 | H16: =COUNTIF(C16:E16,"ج") -> 0 | I16: =COUNTIF(C16:E16,"د") -> 0 | J16: =IF(COUNTIF(C16:E16,"ج")+COUNTIF(C16:E16,"د")>=1,"X"," ")
A17: ='بيانات التلاميذ في المادة '!A17:B17 -> عبد القادر بونوح | C17: ='بيانات التلاميذ في المادة '!G17 -> ج | D17: ='بيانات التلاميذ في المادة '!H17 -> د | E17: ='بيانات التلاميذ في المادة '!I17 -> ج | F17: =COUNTIF(C17:E17,"أ") -> 0 | G17: =COUNTIF(C17:E17,"ب") -> 0 | H17: =COUNTIF(C17:E17,"ج") -> 2 | I17: =COUNTIF(C17:E17,"د") -> 1 | J17: =IF(COUNTIF(C17:E17,"ج")+COUNTIF(C17:E17,"د")>=1,"X"," ") -> X
A18: ='بيانات التلاميذ في المادة '!A18:B18 -> أنفال تجيني | C18: ='بيانات التلاميذ في المادة '!G18 -> أ | D18: ='بيانات التلاميذ في المادة '!H18 -> د | E18: ='بيانات التلاميذ في المادة '!I18 -> د | F18: =COUNTIF(C18:E18,"أ") -> 1 | G18: =COUNTIF(C18:E18,"ب") -> 0 | H18: =COUNTIF(C18:E18,"ج") -> 0 | I18: =COUNTIF(C18:E18,"د") -> 2 | J18: =IF(COUNTIF(C18:E18,"ج")+COUNTIF(C18:E18,"د")>=1,"X"," ") -> X
A19: ='بيانات التلاميذ في المادة '!A19:B19 -> محمد عبد الرحمان تواتي | C19: ='بيانات التلاميذ في المادة '!G19 -> غ | D19: ='بيانات التلاميذ في المادة '!H19 -> غ | E19: ='بيانات التلاميذ في المادة '!I19 -> غ | F19: =COUNTIF(C19:E19,"أ") -> 0 | G19: =COUNTIF(C19:E19,"ب") -> 0 | H19: =COUNTIF(C19:E19,"ج") -> 0 | I19: =COUNTIF(C19:E19,"د") -> 0 | J19: =IF(COUNTIF(C19:E19,"ج")+COUNTIF(C19:E19,"د")>=1,"X"," ")
... A54: ='بيانات التلاميذ في المادة '!A54:B54 -> 0 | C54: ='بيانات التلاميذ في المادة '!G54 -> 0 | D54: ='بيانات التلاميذ في المادة '!H54 -> 0 | E54: ='بيانات التلاميذ في المادة '!I54 -> 0 | F54: =COUNTIF(C54:E54,"أ") -> 0 | G54: =COUNTIF(C54:E54,"ب") -> 0 | H54: =COUNTIF(C54:E54,"ج") -> 0 | I54: =COUNTIF(C54:E54,"د") -> 0 | J54: =IF(COUNTIF(C54:E54,"ج")+COUNTIF(C54:E54,"د")>=1,"X"," ")
A55: أ | C55: =COUNTIF(C5:C54,"أ") -> 18 | D55: =COUNTIF(D5:D54,"أ") -> 20 | E55: =COUNTIF(E5:E54,"أ") -> 17 | F55: =SUM(F5:F54) -> 55 | J55: =COUNTIF(J5:J54,"X") -> 20
A56: ب | C56: =COUNTIF(C5:C54,"ب") -> 8 | D56: =COUNTIF(D5:D54,"ب") -> 7 | E56: =COUNTIF(E5:E54,"ب") -> 8 | G56: =SUM(G6:G55) -> 23
A57: ج | C57: =COUNTIF(C5:C54,"ج") -> 8 | D57: =COUNTIF(D5:D54,"ج") -> 6 | E57: =COUNTIF(E5:E54,"ج") -> 8 | H57: =SUM(H7:H56) -> 22
A58: د | C58: =COUNTIF(C5:C54,"د") -> 6 | D58: =COUNTIF(D5:D54,"د") -> 7 | E58: =COUNTIF(E5:E54,"د") -> 7 | I58: =SUM(I8:I57) -> 17
A59: الغياب | C59: =COUNTIF(C5:C54,"غ") -> 4 | D59: =COUNTIF(D5:D54,"غ") -> 4 | E59: =COUNTIF(E5:E54,"غ") -> 4

Sheet التلاميذ للمعالجة الكفاءة 1
A2: وزارة التربية الوطنية
A3: مديرية التربية لولاية وهران | D3: مادة العلوم الفيزيائية و التكنولوجيا
A4: متوسطة المجاهد بوكرش محمد | D4: الأستاذ محمد صوان
A5: قسم: 1 م 3 | C5: =COUNTA('بيانات التلاميذ في المادة '!$G$5:$G$54)&" "&"تلميذ(ة)" -> 44 تلميذ(ة) | D5: 2023 - 2024
A6: قائمة التلاميذ المعنيين بالمعالجة (الفئة ج + د) حسب المعايير الكفاءة الختامية 1 | F6: المساعد1 | H6: المساعد2 | J6: المساعد3 | L6: المساعد4
F7: =IF(OR('بيانات التلاميذ في المادة '!C5="ج",'بيانات التلاميذ في المادة '!C5=("د")),ROW()-2,"") -> 5 | G7: =IFERROR(SMALL($F$7:$F$54,ROW()-6),"") -> 5 | H7: =IF(OR('بيانات التلاميذ في المادة '!D5="ج",'بيانات التلاميذ في المادة '!D5=("د")),ROW()-2,"") -> 5 | I7: =IFERROR(SMALL($H$7:$H$54,ROW()-6),"") -> 5 | J7: =IF(OR('بيانات التلاميذ في المادة '!E5="ج",'بيانات التلاميذ في المادة '!E5=("د")),ROW()-2,"") -> 5 | K7: =IFERROR(SMALL($J$7:$J$54,ROW()-6),"") -> 5 | L7: =IF(OR('بيانات التلاميذ في المادة '!F5="ج",'بيانات التلاميذ في المادة '!F5=("د")),ROW()-2,"") -> 5 | M7: =IFERROR(SMALL($L$7:$L$54,ROW()-6),"") -> 5
B8: =COUNTA(B11:B45)-COUNTBLANK(B11:B45)&" "&"تلميذ(ة)" -> 10 تلميذ(ة) | C8: =COUNTA(C11:C45)-COUNTBLANK(C11:C45)&" "&"تلميذ(ة)" -> 12 تلميذ(ة) | D8: =COUNTA(D11:D45)-COUNTBLANK(D11:D45)&" "&"تلميذ(ة)" -> 8 تلميذ(ة) | E8: =COUNTA(E11:E45)-COUNTBLANK(E11:E45)&" "&"تلميذ(ة)" -> 10 تلميذ(ة) | F8: =IF(OR('بيانات التلاميذ في المادة '!C6="ج",'بيانات التلاميذ في المادة '!C6=("د")),ROW()-2,"") | G8: =IFERROR(SMALL($F$7:$F$54,ROW()-6),"") -> 11 | H8: =IF(OR('بيانات التلاميذ في المادة '!D6="ج",'بيانات التلاميذ في المادة '!D6=("د")),ROW()-2,"") -> 6 | I8: =IFERROR(SMALL($H$7:$H$54,ROW()-6),"") -> 6 | J8: =IF(OR('بيانات التلاميذ في المادة '!E6="ج",'بيانات التلاميذ في المادة '!E6=("د")),ROW()-2,"") -> 6 | K8: =IFERROR(SMALL($J$7:$J$54,ROW()-6),"") -> 6 | L8: =IF(OR('بيانات التلاميذ في المادة '!F6="ج",'بيانات التلاميذ في المادة '!F6=("د")),ROW()-2,"") -> 6 | M8: =IFERROR(SMALL($L$7:$L$54,ROW()-6),"") -> 6
A9: الرقم | B9: حسب م1 | C9: حسب م2 | D9: حسب م3 | E9: حسب م4 | F9: =IF(OR('بيانات التلاميذ في المادة '!C7="ج",'بيانات التلاميذ في المادة '!C7=("د")),ROW()-2,"") | G9: =IFERROR(SMALL($F$7:$F$54,ROW()-6),"") -> 12 | H9: =IF(OR('بيانات التلاميذ في المادة '!D7="ج",'بيانات التلاميذ في المادة '!D7=("د")),ROW()-2,"") | I9: =IFERROR(SMALL($H$7:$H$54,ROW()-6),"") -> 11 | J9: =IF(OR('بيانات التلاميذ في المادة '!E7="ج",'بيانات التلاميذ في المادة '!E7=("د")),ROW()-2,"") | K9: =IFERROR(SMALL($J$7:$J$54,ROW()-6),"") -> 11 | L9: =IF(OR('بيانات التلاميذ في المادة '!F7="ج",'بيانات التلاميذ في المادة '!F7=("د")),ROW()-2,"") | M9: =IFERROR(SMALL($L$7:$L$54,ROW()-6),"") -> 11
F10: =IF(OR('بيانات التلاميذ في المادة '!C8="ج",'بيانات التلاميذ في المادة '!C8=("د")),ROW()-2,"") | G10: =IFERROR(SMALL($F$7:$F$54,ROW()-6),"") -> 13 | H10: =IF(OR('بيانات التلاميذ في المادة '!D8="ج",'بيانات التلاميذ في المادة '!D8=("د")),ROW()-2,"") | I10: =IFERROR(SMALL($H$7:$H$54,ROW()-6),"") -> 12 | J10: =IF(OR('بيانات التلاميذ في المادة '!E8="ج",'بيانات التلاميذ في المادة '!E8=("د")),ROW()-2,"") | K10: =IFERROR(SMALL($J$7:$J$54,ROW()-6),"") -> 13 | L10: =IF(OR('بيانات التلاميذ في المادة '!F8="ج",'بيانات التلاميذ في المادة '!F8=("د")),ROW()-2,"") | M10: =IFERROR(SMALL($L$7:$L$54,ROW()-6),"") -> 13
A11: =IF(OR((B11<>""),(C11<>""),(D11<>""),(E11<>"")),ROW()-10,"") -> 1 | B11: =IFERROR(INDEX('بيانات التلاميذ في المادة '!$A$5:$A$54,'التلاميذ للمعالجة الكفاءة 1'!G7-4),"") -> ريتاج أمبارك | C11: =IFERROR(INDEX('بيانات التلاميذ في المادة '!$A$5:$A$54,'التلاميذ للمعالجة الكفاءة 1'!I7-4),"") -> ريتاج أمبارك | D11: =IFERROR(INDEX('بيانات التلاميذ في المادة '!$A$5:$A$54,'التلاميذ للمعالجة الكفاءة 1'!K7-4),"") -> ريتاج أمبارك | E11: =IFERROR(INDEX('بيانات التلاميذ في المادة '!$A$5:$A$54,'التلاميذ للمعالجة الكفاءة 1'!M7-4),"") -> ريتاج أمبارك | F11: =IF(OR('بيانات التلاميذ في المادة '!C9="ج",'بيانات التلاميذ في المادة '!C9=("د")),ROW()-2,"") | G11: =IFERROR(SMALL($F$7:$F$54,ROW()-6),"") -> 14 | H11: =IF(OR('بيانات التلاميذ في المادة '!D9="ج",'بيانات التلاميذ في المادة '!D9=("د")),ROW()-2,"") | I11: =IFERROR(SMALL($H$7:$H$54,ROW()-6),"") -> 13 | J11: =IF(OR('بيانات التلاميذ في المادة '!E9="ج",'بيانات التلاميذ في المادة '!E9=("د")),ROW()-2,"") | K11: =IFERROR(SMALL($J$7:$J$54,ROW()-6),"") -> 14 | L11: =IF(OR('بيانات التلاميذ في المادة '!F9="ج",'بيانات التلاميذ في المادة '!F9=("د")),ROW()-2,"") | M11: =IFERROR(SMALL($L$7:$L$54,ROW()-6),"") -> 14
A12: =IF(OR((B12<>""),(C12<>""),(D12<>""),(E12<>"")),ROW()-10,"") -> 2 | B12: =IFERROR(INDEX('بيانات التلاميذ في المادة '!$A$5:$A$54,'التلاميذ للمعالجة الكفاءة 1'!G8-4),"") -> محمد بن طيب | C12: =IFERROR(INDEX('بيانات التلاميذ في المادة '!$A$5:$A$54,'التلاميذ للمعالجة الكفاءة 1'!I8-4),"") -> محمد الرشيد بربارة | D12: =IFERROR(INDEX('بيانات التلاميذ في المادة '!$A$5:$A$54,'التلاميذ للمعالجة الكفاءة 1'!K8-4),"") -> محمد الرشيد بربارة | E12: =IFERROR(INDEX('بيانات التلاميذ في المادة '!$A$5:$A$54,'التلاميذ للمعالجة الكفاءة 1'!M8-4),"") -> محمد الرشيد بربارة | F12: =IF(OR('بيانات التلاميذ في المادة '!C10="ج",'بيانات التلاميذ في المادة '!C10=("د")),ROW()-2,"") | G12: =IFERROR(SMALL($F$7:$F$54,ROW()-6),"") -> 15 | H12: =IF(OR('بيانات التلاميذ في المادة '!D10="ج",'بيانات التلاميذ في المادة '!D10=("د")),ROW()-2,"") | I12: =IFERROR(SMALL($H$7:$H$54,ROW()-6),"") -> 14 | J12: =IF(OR('بيانات التلاميذ في المادة '!E10="ج",'بيانات التلاميذ في المادة '!E10=("د")),ROW()-2,"") | K12: =IFERROR(SMALL($J$7:$J$54,ROW()-6),"") -> 17 | L12: =IF(OR('بيانات التلاميذ في المادة '!F10="ج",'بيانات التلاميذ في المادة '!F10=("د")),ROW()-2,"") | M12: =IFERROR(SMALL($L$7:$L$54,ROW()-6),"") -> 15
A13: =IF(OR((B13<>""),(C13<>""),(D13<>""),(E13<>"")),ROW()-10,"") -> 3 | B13: =IFERROR(INDEX('بيانات التلاميذ في المادة '!$A$5:$A$54,'التلاميذ للمعالجة الكفاءة 1'!G9-4),"") -> نضال سليم بن عابد | C13: =IFERROR(INDEX('بيانات التلاميذ في المادة '!$A$5:$A$54,'التلاميذ للمعالجة الكفاءة 1'!I9-4),"") -> محمد بن طيب | D13: =IFERROR(INDEX('بيانات التلاميذ في المادة '!$A$5:$A$54,'التلاميذ للمعالجة الكفاءة 1'!K9-4),"") -> محمد بن طيب | E13: =IFERROR(INDEX('بيانات التلاميذ في المادة '!$A$5:$A$54,'التلاميذ للمعالجة الكفاءة 1'!M9-4),"") -> محمد بن طيب | F13: =IF(OR('بيانات التلاميذ في المادة '!C11="ج",'بيانات التلاميذ في المادة '!C11=("د")),ROW()-2,"") -> 11 | G13: =IFERROR(SMALL($F$7:$F$54,ROW()-6),"") -> 17 | H13: =IF(OR('بيانات التلاميذ في المادة '!D11="ج",'بيانات التلاميذ في المادة '!D11=("د")),ROW()-2,"") -> 11 | I13: =IFERROR(SMALL($H$7:$H$54,ROW()-6),"") -> 17 | J13: =IF(OR('بيانات التلاميذ في المادة '!E11="ج",'بيانات التلاميذ في المادة '!E11=("د")),ROW()-2,"") -> 11 | K13: =IFERROR(SMALL($J$7:$J$54,ROW()-6),"") -> 26 | L13: =IF(OR('بيانات التلاميذ في المادة '!F11="ج",'بيانات التلاميذ في المادة '!F11=("د")),ROW()-2,"") -> 11 | M13: =IFERROR(SMALL($L$7:$L$54,ROW()-6),"") -> 17
A14: =IF(OR((B14<>""),(C14<>""),(D14<>""),(E14<>"")),ROW()-10,"") -> 4 | B14: =IFERROR(INDEX('بيانات التلاميذ في المادة '!$A$5:$A$54,'التلاميذ للمعالجة الكفاءة 1'!G10-4),"") -> شهرزاد بوراس | C14: =IFERROR(INDEX('بيانات التلاميذ في المادة '!$A$5:$A$54,'التلاميذ للمعالجة الكفاءة 1'!I10-4),"") -> نضال سليم بن عابد | D14: =IFERROR(INDEX('بيانات التلاميذ في المادة '!$A$5:$A$54,'التلاميذ للمعالجة الكفاءة 1'!K10-4),"") -> شهرزاد بوراس | E14: =IFERROR(INDEX('بيانات التلاميذ في المادة '!$A$5:$A$54,'التلاميذ للمعالجة الكفاءة 1'!M10-4),"") -> شهرزاد بوراس | F14: =IF(OR('بيانات التلاميذ في المادة '!C12="ج",'بيانات التلاميذ في المادة '!C12=("د")),ROW()-2,"") -> 12 | G14: =IFERROR(SMALL($F$7:$F$54,ROW()-6),"") -> 24 | H14: =IF(OR('بيانات التلاميذ في المادة '!D12="ج",'بيانات التلاميذ في المادة '!D12=("د")),ROW()-2,"") -> 12 | I14: =IFERROR(SMALL($H$7:$H$54,ROW()-6),"") -> 24 | J14: =IF(OR('بيانات التلاميذ في المادة '!E12="ج",'بيانات التلاميذ في المادة '!E12=("د")),ROW()-2,"") | K14: =IFERROR(SMALL($J$7:$J$54,ROW()-6),"") -> 33 | L14: =IF(OR('بيانات التلاميذ في المادة '!F12="ج",'بيانات التلاميذ في المادة '!F12=("د")),ROW()-2,"") | M14: =IFERROR(SMALL($L$7:$L$54,ROW()-6),"") -> 26
A15: =IF(OR((B15<>""),(C15<>""),(D15<>""),(E15<>"")),ROW()-10,"") -> 5 | B15: =IFERROR(INDEX('بيانات التلاميذ في المادة '!$A$5:$A$54,'التلاميذ للمعالجة الكفاءة 1'!G11-4),"") -> فراح بوزيتونة | C15: =IFERROR(INDEX('بيانات التلاميذ في المادة '!$A$5:$A$54,'التلاميذ للمعالجة الكفاءة 1'!I11-4),"") -> شهرزاد بوراس | D15: =IFERROR(INDEX('بيانات التلاميذ في المادة '!$A$5:$A$54,'التلاميذ للمعالجة الكفاءة 1'!K11-4),"") -> فراح بوزيتونة | E15: =IFERROR(INDEX('بيانات التلاميذ في المادة '!$A$5:$A$54,'التلاميذ للمعالجة الكفاءة 1'!M11-4),"") -> فراح بوزيتونة | F15: =IF(OR('بيانات التلاميذ في المادة '!C13="ج",'بيانات التلاميذ في المادة '!C13=("د")),ROW()-2,"") -> 13 | G15: =IFERROR(SMALL($F$7:$F$54,ROW()-6),"") -> 26 | H15: =IF(OR('بيانات التلاميذ في المادة '!D13="ج",'بيانات التلاميذ في المادة '!D13=("د")),ROW()-2,"") -> 13 | I15: =IFERROR(SMALL($H$7:$H$54,ROW()-6),"") -> 26 | J15: =IF(OR('بيانات التلاميذ في المادة '!E13="ج",'بيانات التلاميذ في المادة '!E13=("د")),ROW()-2,"") -> 13 | K15: =IFERROR(SMALL($J$7:$J$54,ROW()-6),"") | L15: =IF(OR('بيانات التلاميذ في المادة '!F13="ج",'بيانات التلاميذ في المادة '!F13=("د")),ROW()-2,"") -> 13 | M15: =IFERROR(SMALL($L$7:$L$54,ROW()-6),"") -> 27
A16: =IF(OR((B16<>""),(C16<>""),(D16<>""),(E16<>"")),ROW()-10,"") -> 6 | B16: =IFERROR(INDEX('بيانات التلاميذ في المادة '!$A$5:$A$54,'التلاميذ للمعالجة الكفاءة 1'!G12-4),"") -> ياسر عبد المالك بوعلام | C16: =IFERROR(INDEX('بيانات التلاميذ في المادة '!$A$5:$A$54,'التلاميذ للمعالجة الكفاءة 1'!I12-4),"") -> فراح بوزيتونة | D16: =IFERROR(INDEX('بيانات التلاميذ في المادة '!$A$5:$A$54,'التلاميذ للمعالجة الكفاءة 1'!K12-4),"") -> عبد القادر بونوح | E16: =IFERROR(INDEX('بيانات التلاميذ في المادة '!$A$5:$A$54,'التلاميذ للمعالجة الكفاءة 1'!M12-4),"") -> ياسر عبد المالك بوعلام | F16: =IF(OR('بيانات التلاميذ في المادة '!C14="ج",'بيانات التلاميذ في المادة '!C14=("د")),ROW()-2,"") -> 14 | G16: =IFERROR(SMALL($F$7:$F$54,ROW()-6),"") -> 33 | H16: =IF(OR('بيانات التلاميذ في المادة '!D14="ج",'بيانات التلاميذ في المادة '!D14=("د")),ROW()-2,"") -> 14 | I16: =IFERROR(SMALL($H$7:$H$54,ROW()-6),"") -> 27 | J16: =IF(OR('بيانات التلاميذ في المادة '!E14="ج",'بيانات التلاميذ في المادة '!E14=("د")),ROW()-2,"") -> 14 | K16: =IFERROR(SMALL($J$7:$J$54,ROW()-6),"") | L16: =IF(OR('بيانات التلاميذ في المادة '!F14="ج",'بيانات التلاميذ في المادة '!F14=("د")),ROW()-2,"") -> 14 | M16: =IFERROR(SMALL($L$7:$L$54,ROW()-6),"") -> 33
A17: =IF(OR((B17<>""),(C17<>""),(D17<>""),(E17<>"")),ROW()-10,"") -> 7 | B17: =IFERROR(INDEX('بيانات التلاميذ في المادة '!$A$5:$A$54,'التلاميذ للمعالجة الكفاءة 1'!G13-4),"") -> عبد القادر بونوح | C17: =IFERROR(INDEX('بيانات التلاميذ في المادة '!$A$5:$A$54,'التلاميذ للمعالجة الكفاءة 1'!I13-4),"") -> عبد القادر بونوح | D17: =IFERROR(INDEX('بيانات التلاميذ في المادة '!$A$5:$A$54,'التلاميذ للمعالجة الكفاءة 1'!K13-4),"") -> زهير شقرون | E17: =IFERROR(INDEX('بيانات التلاميذ في المادة '!$A$5:$A$54,'التلاميذ للمعالجة الكفاءة 1'!M13-4),"") -> عبد القادر بونوح | F17: =IF(OR('بيانات التلاميذ في المادة '!C15="ج",'بيانات التلاميذ في المادة '!C15=("د")),ROW()-2,"") -> 15 | G17: =IFERROR(SMALL($F$7:$F$54,ROW()-6),"") | H17: =IF(OR('بيانات التلاميذ في المادة '!D15="ج",'بيانات التلاميذ في المادة '!D15=("د")),ROW()-2,"") | I17: =IFERROR(SMALL($H$7:$H$54,ROW()-6),"") -> 33 | J17: =IF(OR('بيانات التلاميذ في المادة '!E15="ج",'بيانات التلاميذ في المادة '!E15=("د")),ROW()-2,"") | K17: =IFERROR(SMALL($J$7:$J$54,ROW()-6),"") | L17: =IF(OR('بيانات التلاميذ في المادة '!F15="ج",'بيانات التلاميذ في المادة '!F15=("د")),ROW()-2,"") -> 15 | M17: =IFERROR(SMALL($L$7:$L$54,ROW()-6),"")
A18: =IF(OR((B18<>""),(C18<>""),(D18<>""),(E18<>"")),ROW()-10,"") -> 8 | B18: =IFERROR(INDEX('بيانات التلاميذ في المادة '!$A$5:$A$54,'التلاميذ للمعالجة الكفاءة 1'!G14-4),"") -> مصطفى محمد سماحي | C18: =IFERROR(INDEX('بيانات التلاميذ في المادة '!$A$5:$A$54,'التلاميذ للمعالجة الكفاءة 1'!I14-4),"") -> مصطفى محمد سماحي | D18: =IFERROR(INDEX('بيانات التلاميذ في المادة '!$A$5:$A$54,'التلاميذ للمعالجة الكفاءة 1'!K14-4),"") -> انس لحمر عبو | E18: =IFERROR(INDEX('بيانات التلاميذ في المادة '!$A$5:$A$54,'التلاميذ للمعالجة الكفاءة 1'!M14-4),"") -> زهير شقرون | F18: =IF(OR('بيانات التلاميذ في المادة '!C16="ج",'بيانات التلاميذ في المادة '!C16=("د")),ROW()-2,"") | G18: =IFERROR(SMALL($F$7:$F$54,ROW()-6),"") | H18: =IF(OR('بيانات التلاميذ في المادة '!D16="ج",'بيانات التلاميذ في المادة '!D16=("د")),ROW()-2,"") | I18: =IFERROR(SMALL($H$7:$H$54,ROW()-6),"") -> 40 | J18: =IF(OR('بيانات التلاميذ في المادة '!E16="ج",'بيانات التلاميذ في المادة '!E16=("د")),ROW()-2,"") | K18: =IFERROR(SMALL($J$7:$J$54,ROW()-6),"") | L18: =IF(OR('بيانات التلاميذ في المادة '!F16="ج",'بيانات التلاميذ في المادة '!F16=("د")),ROW()-2,"") | M18: =IFERROR(SMALL($L$7:$L$54,ROW()-6),"")
A19: =IF(OR((B19<>""),(C19<>""),(D19<>""),(E19<>"")),ROW()-10,"") -> 9 | B19: =IFERROR(INDEX('بيانات التلاميذ في المادة '!$A$5:$A$54,'التلاميذ للمعالجة الكفاءة 1'!G15-4),"") -> زهير شقرون | C19: =IFERROR(INDEX('بيانات التلاميذ في المادة '!$A$5:$A$54,'التلاميذ للمعالجة الكفاءة 1'!I15-4),"") -> زهير شقرون | D19: =IFERROR(INDEX('بيانات التلاميذ في المادة '!$A$5:$A$54,'التلاميذ للمعالجة الكفاءة 1'!K15-4),"") | E19: =IFERROR(INDEX('بيانات التلاميذ في المادة '!$A$5:$A$54,'التلاميذ للمعالجة الكفاءة 1'!M15-4),"") -> فايزة شلابي | F19: =IF(OR('بيانات التلاميذ في المادة '!C17="ج",'بيانات التلاميذ في المادة '!C17=("د")),ROW()-2,"") -> 17 | G19: =IFERROR(SMALL($F$7:$F$54,ROW()-6),"") | H19: =IF(OR('بيانات التلاميذ في المادة '!D17="ج",'بيانات التلاميذ في المادة '!D17=("د")),ROW()-2,"") -> 17 | I19: =IFERROR(SMALL($H$7:$H$54,ROW()-6),"") | J19: =IF(OR('بيانات التلاميذ في المادة '!E17="ج",'بيانات التلاميذ في المادة '!E17=("د")),ROW()-2,"") -> 17 | K19: =IFERROR(SMALL($J$7:$J$54,ROW()-6),"") | L19: =IF(OR('بيانات التلاميذ في المادة '!F17="ج",'بيانات التلاميذ في المادة '!F17=("د")),ROW()-2,"") -> 17 | M19: =IFERROR(SMALL($L$7:$L$54,ROW()-6),"")
A20: =IF(OR((B20<>""),(C20<>""),(D20<>""),(E20<>"")),ROW()-10,"") -> 10 | B20: =IFERROR(INDEX('بيانات التلاميذ في المادة '!$A$5:$A$54,'التلاميذ للمعالجة الكفاءة 1'!G16-4),"") -> انس لحمر عبو | C20: =IFERROR(INDEX('بيانات التلاميذ في المادة '!$A$5:$A$54,'التلاميذ للمعالجة الكفاءة 1'!I16-4),"") -> فايزة شلابي | D20: =IFERROR(INDEX('بيانات التلاميذ في المادة '!$A$5:$A$54,'التلاميذ للمعالجة الكفاءة 1'!K16-4),"") | E20: =IFERROR(INDEX('بيانات التلاميذ في المادة '!$A$5:$A$54,'التلاميذ للمعالجة الكفاءة 1'!M16-4),"") -> انس لحمر عبو | F20: =IF(OR('بيانات التلاميذ في المادة '!C18="ج",'بيانات التلاميذ في المادة '!C18=("د")),ROW()-2,"") | G20: =IFERROR(SMALL($F$7:$F$54,ROW()-6),"") | H20: =IF(OR('بيانات التلاميذ في المادة '!D18="ج",'بيانات التلاميذ في المادة '!D18=("د")),ROW()-2,"") | I20: =IFERROR(SMALL($H$7:$H$54,ROW()-6),"") | J20: =IF(OR('بيانات التلاميذ في المادة '!E18="ج",'بيانات التلاميذ في المادة '!E18=("د")),ROW()-2,"") | K20: =IFERROR(SMALL($J$7:$J$54,ROW()-6),"") | L20: =IF(OR('بيانات التلاميذ في المادة '!F18="ج",'بيانات التلاميذ في المادة '!F18=("د")),ROW()-2,"") | M20: =IFERROR(SMALL($L$7:$L$54,ROW()-6),"")
A21: =IF(OR((B21<>""),(C21<>""),(D21<>""),(E21<>"")),ROW()-10,"") -> 11 | B21: =IFERROR(INDEX('بيانات التلاميذ في المادة '!$A$5:$A$54,'التلاميذ للمعالجة الكفاءة 1'!G17-4),"") | C21: =IFERROR(INDEX('بيانات التلاميذ في المادة '!$A$5:$A$54,'التلاميذ للمعالجة الكفاءة 1'!I17-4),"") -> انس لحمر عبو | D21: =IFERROR(INDEX('بيانات التلاميذ في المادة '!$A$5:$A$54,'التلاميذ للمعالجة الكفاءة 1'!K17-4),"") | E21: =IFERROR(INDEX('بيانات التلاميذ في المادة '!$A$5:$A$54,'التلاميذ للمعالجة الكفاءة 1'!M17-4),"") | F21: =IF(OR('بيانات التلاميذ في المادة '!C19="ج",'بيانات التلاميذ في المادة '!C19=("د")),ROW()-2,"") | G21: =IFERROR(SMALL($F$7:$F$54,ROW()-6),"") | H21: =IF(OR('بيانات التلاميذ في المادة '!D19="ج",'بيانات التلاميذ في المادة '!D19=("د")),ROW()-2,"") | I21: =IFERROR(SMALL($H$7:$H$54,ROW()-6),"") | J21: =IF(OR('بيانات التلاميذ في المادة '!E19="ج",'بيانات التلاميذ في المادة '!E19=("د")),ROW()-2,"") | K21: =IFERROR(SMALL($J$7:$J$54,ROW()-6),"") | L21: =IF(OR('بيانات التلاميذ في المادة '!F19="ج",'بيانات التلاميذ في المادة '!F19=("د")),ROW()-2,"") | M21: =IFERROR(SMALL($L$7:$L$54,ROW()-6),"")
A22: =IF(OR((B22<>""),(C22<>""),(D22<>""),(E22<>"")),ROW()-10,"") -> 12 | B22: =IFERROR(INDEX('بيانات التلاميذ في المادة '!$A$5:$A$54,'التلاميذ للمعالجة الكفاءة 1'!G18-4),"") | C22: =IFERROR(INDEX('بيانات التلاميذ في المادة '!$A$5:$A$54,'التلاميذ للمعالجة الكفاءة 1'!I18-4),"") -> مروى مخفي | D22: =IFERROR(INDEX('بيانات التلاميذ في المادة '!$A$5:$A$54,'التلاميذ للمعالجة الكفاءة 1'!K18-4),"") | E22: =IFERROR(INDEX('بيانات التلاميذ في المادة '!$A$5:$A$54,'التلاميذ للمعالجة الكفاءة 1'!M18-4),"") | F22: =IF(OR('بيانات التلاميذ في المادة '!C20="ج",'بيانات التلاميذ في المادة '!C20=("د")),ROW()-2,"") | G22: =IFERROR(SMALL($F$7:$F$54,ROW()-6),"") | H22: =IF(OR('بيانات التلاميذ في المادة '!D20="ج",'بيانات التلاميذ في المادة '!D20=("د")),ROW()-2,"") | I22: =IFERROR(SMALL($H$7:$H$54,ROW()-6),"") | J22: =IF(OR('بيانات التلاميذ في المادة '!E20="ج",'بيانات التلاميذ في المادة '!E20=("د")),ROW()-2,"") | K22: =IFERROR(SMALL($J$7:$J$54,ROW()-6),"") | L22: =IF(OR('بيانات التلاميذ في المادة '!F20="ج",'بيانات التلاميذ في المادة '!F20=("د")),ROW()-2,"") | M22: =IFERROR(SMALL($L$7:$L$54,ROW()-6),"")
... A45: =IF(OR((B45<>""),(C45<>""),(D45<>""),(E45<>"")),ROW()-10,"") | B45: =IFERROR(INDEX('بيانات التلاميذ في المادة '!$A$5:$A$54,'التلاميذ للمعالجة الكفاءة 1'!G41-4),"") | C45: =IFERROR(INDEX('بيانات التلاميذ في المادة '!$A$5:$A$54,'التلاميذ للمعالجة الكفاءة 1'!I41-4),"") | D45: =IFERROR(INDEX('بيانات التلاميذ في المادة '!$A$5:$A$54,'التلاميذ للمعالجة الكفاءة 1'!K41-4),"") | E45: =IFERROR(INDEX('بيانات التلاميذ في المادة '!$A$5:$A$54,'التلاميذ للمعالجة الكفاءة 1'!M41-4),"") | F45: =IF(OR('بيانات التلاميذ في المادة '!C43="ج",'بيانات التلاميذ في المادة '!C43=("د")),ROW()-2,"") | G45: =IFERROR(SMALL($F$7:$F$54,ROW()-6),"") | H45: =IF(OR('بيانات التلاميذ في المادة '!D43="ج",'بيانات التلاميذ في المادة '!D43=("د")),ROW()-2,"") | I45: =IFERROR(SMALL($H$7:$H$54,ROW()-6),"") | J45: =IF(OR('بيانات التلاميذ في المادة '!E43="ج",'بيانات التلاميذ في المادة '!E43=("د")),ROW()-2,"") | K45: =IFERROR(SMALL($J$7:$J$54,ROW()-6),"") | L45: =IF(OR('بيانات التلاميذ في المادة '!F43="ج",'بيانات التلاميذ في المادة '!F43=("د")),ROW()-2,"") | M45: =IFERROR(SMALL($L$7:$L$54,ROW()-6),"")
F46: =IF(OR('بيانات التلاميذ في المادة '!C44="ج",'بيانات التلاميذ في المادة '!C44=("د")),ROW()-2,"") | G46: =IFERROR(SMALL($F$7:$F$54,ROW()-6),"") | H46: =IF(OR('بيانات التلاميذ في المادة '!D44="ج",'بيانات التلاميذ في المادة '!D44=("د")),ROW()-2,"") | I46: =IFERROR(SMALL($H$7:$H$54,ROW()-6),"") | J46: =IF(OR('بيانات التلاميذ في المادة '!E44="ج",'بيانات التلاميذ في المادة '!E44=("د")),ROW()-2,"") | K46: =IFERROR(SMALL($J$7:$J$54,ROW()-6),"") | L46: =IF(OR('بيانات التلاميذ في المادة '!F44="ج",'بيانات التلاميذ في المادة '!F44=("د")),ROW()-2,"") | M46: =IFERROR(SMALL($L$7:$L$54,ROW()-6),"")
A47: أ | B47: ='بيانات التلاميذ في المادة '!C55/COUNTA('بيانات التلاميذ في المادة '!$G$5:$G$54) -> 0.38636364 | C47: ='بيانات التلاميذ في المادة '!D55/COUNTA('بيانات التلاميذ في المادة '!$G$5:$G$54) -> 0.40909091 | D47: ='بيانات التلاميذ في المادة '!E55/COUNTA('بيانات التلاميذ في المادة '!$G$5:$G$54) -> 0.38636364 | E47: ='بيانات التلاميذ في المادة '!F55/COUNTA('بيانات التلاميذ في المادة '!$G$5:$G$54) -> 0.38636364 | F47: =IF(OR('بيانات التلاميذ في المادة '!C45="ج",'بيانات التلاميذ في المادة '!C45=("د")),ROW()-2,"") | G47: =IFERROR(SMALL($F$7:$F$54,ROW()-6),"") | H47: =IF(OR('بيانات التلاميذ في المادة '!D45="ج",'بيانات التلاميذ في المادة '!D45=("د")),ROW()-2,"") | I47: =IFERROR(SMALL($H$7:$H$54,ROW()-6),"") | J47: =IF(OR('بيانات التلاميذ في المادة '!E45="ج",'بيانات التلاميذ في المادة '!E45=("د")),ROW()-2,"") | K47: =IFERROR(SMALL($J$7:$J$54,ROW()-6),"") | L47: =IF(OR('بيانات التلاميذ في المادة '!F45="ج",'بيانات التلاميذ في المادة '!F45=("د")),ROW()-2,"") | M47: =IFERROR(SMALL($L$7:$L$54,ROW()-6),"")
A48: ب | B48: ='بيانات التلاميذ في المادة '!C56/COUNTA('بيانات التلاميذ في المادة '!$G$5:$G$54) -> 0.29545455 | C48: ='بيانات التلاميذ في المادة '!D56/COUNTA('بيانات التلاميذ في المادة '!$G$5:$G$54) -> 0.22727273 | D48: ='بيانات التلاميذ في المادة '!E56/COUNTA('بيانات التلاميذ في المادة '!$G$5:$G$54) -> 0.34090909 | E48: ='بيانات التلاميذ في المادة '!F56/COUNTA('بيانات التلاميذ في المادة '!$G$5:$G$54) -> 0.29545455 | F48: =IF(OR('بيانات التلاميذ في المادة '!C46="ج",'بيانات التلاميذ في المادة '!C46=("د")),ROW()-2,"") | G48: =IFERROR(SMALL($F$7:$F$54,ROW()-6),"") | H48: =IF(OR('بيانات التلاميذ في المادة '!D46="ج",'بيانات التلاميذ في المادة '!D46=("د")),ROW()-2,"") | I48: =IFERROR(SMALL($H$7:$H$54,ROW()-6),"") | J48: =IF(OR('بيانات التلاميذ في المادة '!E46="ج",'بيانات التلاميذ في المادة '!E46=("د")),ROW()-2,"") | K48: =IFERROR(SMALL($J$7:$J$54,ROW()-6),"") | L48: =IF(OR('بيانات التلاميذ في المادة '!F46="ج",'بيانات التلاميذ في المادة '!F46=("د")),ROW()-2,"") | M48: =IFERROR(SMALL($L$7:$L$54,ROW()-6),"")
A49: ج | B49: ='بيانات التلاميذ في المادة '!C57/COUNTA('بيانات التلاميذ في المادة '!$G$5:$G$54) -> 0.15909091 | C49: ='بيانات التلاميذ في المادة '!D57/COUNTA('بيانات التلاميذ في المادة '!$G$5:$G$54) -> 0.25 | D49: ='بيانات التلاميذ في المادة '!E57/COUNTA('بيانات التلاميذ في المادة '!$G$5:$G$54) -> 0.15909091 | E49: ='بيانات التلاميذ في المادة '!F57/COUNTA('بيانات التلاميذ في المادة '!$G$5:$G$54) -> 0.15909091 | F49: =IF(OR('بيانات التلاميذ في المادة '!C47="ج",'بيانات التلاميذ في المادة '!C47=("د")),ROW()-2,"") | G49: =IFERROR(SMALL($F$7:$F$54,ROW()-6),"") | H49: =IF(OR('بيانات التلاميذ في المادة '!D47="ج",'بيانات التلاميذ في المادة '!D47=("د")),ROW()-2,"") | I49: =IFERROR(SMALL($H$7:$H$54,ROW()-6),"") | J49: =IF(OR('بيانات التلاميذ في المادة '!E47="ج",'بيانات التلاميذ في المادة '!E47=("د")),ROW()-2,"") | K49: =IFERROR(SMALL($J$7:$J$54,ROW()-6),"") | L49: =IF(OR('بيانات التلاميذ في المادة '!F47="ج",'بيانات التلاميذ في المادة '!F47=("د")),ROW()-2,"") | M49: =IFERROR(SMALL($L$7:$L$54,ROW()-6),"")
A50: د | B50: ='بيانات التلاميذ في المادة '!C58/COUNTA('بيانات التلاميذ في المادة '!$G$5:$G$54) -> 0.068181818 | C50: ='بيانات التلاميذ في المادة '!D58/COUNTA('بيانات التلاميذ في المادة '!$G$5:$G$54) -> 0.022727273 | D50: ='بيانات التلاميذ في المادة '!E58/COUNTA('بيانات التلاميذ في المادة '!$G$5:$G$54) -> 0.022727273 | E50: ='بيانات التلاميذ في المادة '!F58/COUNTA('بيانات التلاميذ في المادة '!$G$5:$G$54) -> 0.068181818 | F50: =IF(OR('بيانات التلاميذ في المادة '!C48="ج",'بيانات التلاميذ في المادة '!C48=("د")),ROW()-2,"") | G50: =IFERROR(SMALL($F$7:$F$54,ROW()-6),"") | H50: =IF(OR('بيانات التلاميذ في المادة '!D48="ج",'بيانات التلاميذ في المادة '!D48=("د")),ROW()-2,"") | I50: =IFERROR(SMALL($H$7:$H$54,ROW()-6),"") | J50: =IF(OR('بيانات التلاميذ في المادة '!E48="ج",'بيانات التلاميذ في المادة '!E48=("د")),ROW()-2,"") | K50: =IFERROR(SMALL($J$7:$J$54,ROW()-6),"") | L50: =IF(OR('بيانات التلاميذ في المادة '!F48="ج",'بيانات التلاميذ في المادة '!F48=("د")),ROW()-2,"") | M50: =IFERROR(SMALL($L$7:$L$54,ROW()-6),"")
A51: الغياب | B51: ='بيانات التلاميذ في المادة '!C59/COUNTA('بيانات التلاميذ في المادة '!$G$5:$G$54) -> 0.090909091 | C51: ='بيانات التلاميذ في المادة '!D59/COUNTA('بيانات التلاميذ في المادة '!$G$5:$G$54) -> 0.090909091 | D51: ='بيانات التلاميذ في المادة '!E59/COUNTA('بيانات التلاميذ في المادة '!$G$5:$G$54) -> 0.090909091 | E51: ='بيانات التلاميذ في المادة '!F59/COUNTA('بيانات التلاميذ في المادة '!$G$5:$G$54) -> 0.090909091 | F51: =IF(OR('بيانات التلاميذ في المادة '!C49="ج",'بيانات التلاميذ في المادة '!C49=("د")),ROW()-2,"") | G51: =IFERROR(SMALL($F$7:$F$54,ROW()-6),"") | H51: =IF(OR('بيانات التلاميذ في المادة '!D49="ج",'بيانات التلاميذ في المادة '!D49=("د")),ROW()-2,"") | I51: =IFERROR(SMALL($H$7:$H$54,ROW()-6),"") | J51: =IF(OR('بيانات التلاميذ في المادة '!E49="ج",'بيانات التلاميذ في المادة '!E49=("د")),ROW()-2,"") | K51: =IFERROR(SMALL($J$7:$J$54,ROW()-6),"") | L51: =IF(OR('بيانات التلاميذ في المادة '!F49="ج",'بيانات التلاميذ في المادة '!F49=("د")),ROW()-2,"") | M51: =IFERROR(SMALL($L$7:$L$54,ROW()-6),"")
F52: =IF(OR('بيانات التلاميذ في المادة '!C50="ج",'بيانات التلاميذ في المادة '!C50=("د")),ROW()-2,"") | G52: =IFERROR(SMALL($F$7:$F$54,ROW()-6),"") | H52: =IF(OR('بيانات التلاميذ في المادة '!D50="ج",'بيانات التلاميذ في المادة '!D50=("د")),ROW()-2,"") | I52: =IFERROR(SMALL($H$7:$H$54,ROW()-6),"") | J52: =IF(OR('بيانات التلاميذ في المادة '!E50="ج",'بيانات التلاميذ في المادة '!E50=("د")),ROW()-2,"") | K52: =IFERROR(SMALL($J$7:$J$54,ROW()-6),"") | L52: =IF(OR('بيانات التلاميذ في المادة '!F50="ج",'بيانات التلاميذ في المادة '!F50=("د")),ROW()-2,"") | M52: =IFERROR(SMALL($L$7:$L$54,ROW()-6),"")
F53: =IF(OR('بيانات التلاميذ في المادة '!C51="ج",'بيانات التلاميذ في المادة '!C51=("د")),ROW()-2,"") | G53: =IFERROR(SMALL($F$7:$F$54,ROW()-6),"") | H53: =IF(OR('بيانات التلاميذ في المادة '!D51="ج",'بيانات التلاميذ في المادة '!D51=("د")),ROW()-2,"") | I53: =IFERROR(SMALL($H$7:$H$54,ROW()-6),"") | J53: =IF(OR('بيانات التلاميذ في المادة '!E51="ج",'بيانات التلاميذ في المادة '!E51=("د")),ROW()-2,"") | K53: =IFERROR(SMALL($J$7:$J$54,ROW()-6),"") | L53: =IF(OR('بيانات التلاميذ في المادة '!F51="ج",'بيانات التلاميذ في المادة '!F51=("د")),ROW()-2,"") | M53: =IFERROR(SMALL($L$7:$L$54,ROW()-6),"")
F54: =IF(OR('بيانات التلاميذ في المادة '!C52="ج",'بيانات التلاميذ في المادة '!C52=("د")),ROW()-2,"") | G54: =IFERROR(SMALL($F$7:$F$54,ROW()-6),"") | H54: =IF(OR('بيانات التلاميذ في المادة '!D52="ج",'بيانات التلاميذ في المادة '!D52=("د")),ROW()-2,"") | I54: =IFERROR(SMALL($H$7:$H$54,ROW()-6),"") | J54: =IF(OR('بيانات التلاميذ في المادة '!E52="ج",'بيانات التلاميذ في المادة '!E52=("د")),ROW()-2,"") | K54: =IFERROR(SMALL($J$7:$J$54,ROW()-6),"") | L54: =IF(OR('بيانات التلاميذ في المادة '!F52="ج",'بيانات التلاميذ في المادة '!F52=("د")),ROW()-2,"") | M54: =IFERROR(SMALL($L$7:$L$54,ROW()-6),"")

Sheet التلاميذ للمعالجة الكفاءة 2
A2: وزارة التربية الوطنية
A3: مديرية التربية لولاية وهران | D3: مادة العلوم الفيزيائية و التكنولوجيا
A4: متوسطة المجاهد بوكرش محمد | D4: الأستاذ محمد صوان
A5: قسم: 1 م 3 | C5: =COUNTA('بيانات التلاميذ في المادة '!$G$5:$G$54)&" "&"تلميذ(ة)" -> 44 تلميذ(ة) | D5: 2023 - 2024
A6: قائمة التلاميذ المعنيين بالمعالجة (الفئة ج + د) حسب المعايير الكفاءة الختامية 2 | F6: المساعد1 | H6: المساعد2 | J6: المساعد3
F7: =IF(OR('بيانات التلاميذ في المادة '!G5="ج",'بيانات التلاميذ في المادة '!G5=("د")),ROW()-2,"") -> 5 | G7: =IFERROR(SMALL($F$7:$F$50,ROW()-6),"") -> 5 | H7: =IF(OR('بيانات التلاميذ في المادة '!H5="ج",'بيانات التلاميذ في المادة '!H5=("د")),ROW()-2,"") -> 5 | I7: =IFERROR(SMALL($H$7:$H$50,ROW()-6),"") -> 5 | J7: =IF(OR('بيانات التلاميذ في المادة '!I5="ج",'بيانات التلاميذ في المادة '!I5=("د")),ROW()-2,"") -> 5 | K7: =IFERROR(SMALL($J$7:$J$50,ROW()-6),"") -> 5
B8: =COUNTA(B11:B45)-COUNTBLANK(B11:B45)&" "&"تلميذ(ة)" -> 12 تلميذ(ة) | C8: =COUNTA(C11:C45)-COUNTBLANK(C11:C45)&" "&"تلميذ(ة)" -> 13 تلميذ(ة) | D8: =COUNTA(D11:D45)-COUNTBLANK(D11:D45)&" "&"تلميذ(ة)" -> 15 تلميذ(ة) | F8: =IF(OR('بيانات التلاميذ في المادة '!G6="ج",'بيانات التلاميذ في المادة '!G6=("د")),ROW()-2,"") | G8: =IFERROR(SMALL($F$7:$F$46,ROW()-6),"") -> 11 | H8: =IF(OR('بيانات التلاميذ في المادة '!H6="ج",'بيانات التلاميذ في المادة '!H6=("د")),ROW()-2,"") | I8: =IFERROR(SMALL($H$7:$H$50,ROW()-6),"") -> 11 | J8: =IF(OR('بيانات التلاميذ في المادة '!I6="ج",'بيانات التلاميذ في المادة '!I6=("د")),ROW()-2,"") | K8: =IFERROR(SMALL($J$7:$J$50,ROW()-6),"") -> 8
A9: الرقم | B9: حسب م1 | C9: حسب م2 | D9: حسب م3 | F9: =IF(OR('بيانات التلاميذ في المادة '!G7="ج",'بيانات التلاميذ في المادة '!G7=("د")),ROW()-2,"") | G9: =IFERROR(SMALL($F$7:$F$46,ROW()-6),"") -> 12 | H9: =IF(OR('بيانات التلاميذ في المادة '!H7="ج",'بيانات التلاميذ في المادة '!H7=("د")),ROW()-2,"") | I9: =IFERROR(SMALL($H$7:$H$50,ROW()-6),"") -> 13 | J9: =IF(OR('بيانات التلاميذ في المادة '!I7="ج",'بيانات التلاميذ في المادة '!I7=("د")),ROW()-2,"") | K9: =IFERROR(SMALL($J$7:$J$50,ROW()-6),"") -> 11
F10: =IF(OR('بيانات التلاميذ في المادة '!G8="ج",'بيانات التلاميذ في المادة '!G8=("د")),ROW()-2,"") | G10: =IFERROR(SMALL($F$7:$F$46,ROW()-6),"") -> 14 | H10: =IF(OR('بيانات التلاميذ في المادة '!H8="ج",'بيانات التلاميذ في المادة '!H8=("د")),ROW()-2,"") | I10: =IFERROR(SMALL($H$7:$H$50,ROW()-6),"") -> 14 | J10: =IF(OR('بيانات التلاميذ في المادة '!I8="ج",'بيانات التلاميذ في المادة '!I8=("د")),ROW()-2,"") -> 8 | K10: =IFERROR(SMALL($J$7:$J$50,ROW()-6),"") -> 13
A11: =IF(OR((B11<>""),(C11<>""),(D11<>""),(E11<>"")),ROW()-10,"") -> 1 | B11: =IFERROR(INDEX('بيانات التلاميذ في المادة '!$A$5:$A$54,'التلاميذ للمعالجة الكفاءة 2'!G7-4),"") -> ريتاج أمبارك | C11: =IFERROR(INDEX('بيانات التلاميذ في المادة '!$A$5:$A$54,'التلاميذ للمعالجة الكفاءة 2'!I7-4),"") -> ريتاج أمبارك | D11: =IFERROR(INDEX('بيانات التلاميذ في المادة '!$A$5:$A$54,'التلاميذ للمعالجة الكفاءة 2'!K7-4),"") -> ريتاج أمبارك | F11: =IF(OR('بيانات التلاميذ في المادة '!G9="ج",'بيانات التلاميذ في المادة '!G9=("د")),ROW()-2,"") | G11: =IFERROR(SMALL($F$7:$F$46,ROW()-6),"") -> 15 | H11: =IF(OR('بيانات التلاميذ في المادة '!H9="ج",'بيانات التلاميذ في المادة '!H9=("د")),ROW()-2,"") | I11: =IFERROR(SMALL($H$7:$H$50,ROW()-6),"") -> 15 | J11: =IF(OR('بيانات التلاميذ في المادة '!I9="ج",'بيانات التلاميذ في المادة '!I9=("د")),ROW()-2,"") | K11: =IFERROR(SMALL($J$7:$J$50,ROW()-6),"") -> 14
A12: =IF(OR((B12<>""),(C12<>""),(D12<>""),(E12<>"")),ROW()-10,"") -> 2 | B12: =IFERROR(INDEX('بيانات التلاميذ في المادة '!$A$5:$A$54,'التلاميذ للمعالجة الكفاءة 2'!G8-4),"") -> محمد بن طيب | C12: =IFERROR(INDEX('بيانات التلاميذ في المادة '!$A$5:$A$54,'التلاميذ للمعالجة الكفاءة 2'!I8-4),"") -> محمد بن طيب | D12: =IFERROR(INDEX('بيانات التلاميذ في المادة '!$A$5:$A$54,'التلاميذ للمعالجة الكفاءة 2'!K8-4),"") -> بن علي بن زوبير | F12: =IF(OR('بيانات التلاميذ في المادة '!G10="ج",'بيانات التلاميذ في المادة '!G10=("د")),ROW()-2,"") | G12: =IFERROR(SMALL($F$7:$F$46,ROW()-6),"") -> 17 | H12: =IF(OR('بيانات التلاميذ في المادة '!H10="ج",'بيانات التلاميذ في المادة '!H10=("د")),ROW()-2,"") | I12: =IFERROR(SMALL($H$7:$H$50,ROW()-6),"") -> 17 | J12: =IF(OR('بيانات التلاميذ في المادة '!I10="ج",'بيانات التلاميذ في المادة '!I10=("د")),ROW()-2,"") | K12: =IFERROR(SMALL($J$7:$J$50,ROW()-6),"") -> 15
A13: =IF(OR((B13<>""),(C13<>""),(D13<>""),(E13<>"")),ROW()-10,"") -> 3 | B13: =IFERROR(INDEX('بيانات التلاميذ في المادة '!$A$5:$A$54,'التلاميذ للمعالجة الكفاءة 2'!G9-4),"") -> نضال سليم بن عابد | C13: =IFERROR(INDEX('بيانات التلاميذ في المادة '!$A$5:$A$54,'التلاميذ للمعالجة الكفاءة 2'!I9-4),"") -> شهرزاد بوراس | D13: =IFERROR(INDEX('بيانات التلاميذ في المادة '!$A$5:$A$54,'التلاميذ للمعالجة الكفاءة 2'!K9-4),"") -> محمد بن طيب | F13: =IF(OR('بيانات التلاميذ في المادة '!G11="ج",'بيانات التلاميذ في المادة '!G11=("د")),ROW()-2,"") -> 11 | G13: =IFERROR(SMALL($F$7:$F$46,ROW()-6),"") -> 22 | H13: =IF(OR('بيانات التلاميذ في المادة '!H11="ج",'بيانات التلاميذ في المادة '!H11=("د")),ROW()-2,"") -> 11 | I13: =IFERROR(SMALL($H$7:$H$50,ROW()-6),"") -> 18 | J13: =IF(OR('بيانات التلاميذ في المادة '!I11="ج",'بيانات التلاميذ في المادة '!I11=("د")),ROW()-2,"") -> 11 | K13: =IFERROR(SMALL($J$7:$J$50,ROW()-6),"") -> 17
